Workbook
Name SegmentaciónDeDatos_teamName: #N/A

Sheet Datos
A1: gameId | B1: teamCity | C1: teamName | D1: teamId | E1: teamgameId | F1: opponentTeamCity | G1: opponentTeamName | H1: opponentTeamId | I1: oppoteamgameId | J1: home | K1: win | L1: teamScore | M1: opponentScore | N1: assists | O1: blocks | P1: steals | Q1: trueShooting% | R1: estimatedPossessions | S1: estimatedPossessionsOpponent | T1: offensiveRating | U1: defensiveRating | V1: netRating | W1: assists/turnoverRatio | X1: fieldGoalsAttempted | Y1: fieldGoalsMade | Z1: fieldGoalsPercentage | AA1: threePointersAttempted | AB1: threePointersMade | AC1: threePointers | AD1: threePointersPercentage | AE1: freeThrowsAttempted | AF1: freeThrowsMade | AG1: freeThrowsPercentage | AH1: reboundsDefensive | AI1: reboundsOffensive | AJ1: reboundsTotal | AK1: foulsPersonal | AL1: turnovers | AM1: plusMinusPoints | AN1: numMinutes | AO1: q1Points | AP1: q2Points | AQ1: q3Points | AR1: q4Points | AS1: biggestLead | AT1: pointsFastBreak | AU1: pointsFromTurnovers | AV1: pointsInThePaint | AW1: midDistancePoints | AX1: PointsInTheArea | AY1: gameType | AZ1: gameDate | BA1: gameOnlyDate | BB1: Mes | BC1: Nombre del mes | BD1: Año
A2: 42500405 | B2: San Antonio | C2: Spurs | D2: 1610612759 | E2: =D2:D2645&A2:A2645 -> 161061275942500405 | F2: New York | G2: Knicks | H2: 1610612752 | I2: =H2:H2645&A2:A2645 -> 161061275242500405 | J2: 1 | K2: 0 | L2: 90 | M2: 94 | N2: 18 | O2: 7 | P2: 6 | Q2: =IF((2*(X2 + 0.44 * AE2))=0,0,L2 / (2*(X2 + 0.44 * AE2))) -> 0.47689699 | R2: =X2 + 0.44 * AE2 - AI2 - AL2 -> 68.36 | S2: =INDEX(X:X,MATCH(I2,E:E,0)) +0.44*INDEX(AE:AE,MATCH(I2,E:E,0)) -INDEX(AI:AI,MATCH(I2,E:E,0)) -INDEX(AL:AL,MATCH(I2,E:E,0)) -> 76.32 | T2: =(L2/R2)*100 -> 131.65594 | U2: =(M2/S2)*100 -> 123.16562 | V2: =T2-U2 -> 8.4903207 | W2: =N2/IF(AL2=0,1,AL2) -> 1.5 | X2: 86 | Y2: 33 | Z2: 0.384 | AA2: 37 | AB2: 12 | AC2: =AB2*3 -> 36 | AD2: 0.324 | AE2: 19 | AF2: 12 | AG2: 0.632 | AH2: 33 | AI2: 14 | AJ2: 47 | AK2: 22 | AL2: 12 | AM2: -4 | AN2: 240 | AO2: 23 | AP2: 19 | AQ2: 30 | AR2: 18 | AS2: 16 | AT2: 13 | AU2: 21 | AV2: 38 | AW2: =L2-(AV2+AC2+AF2) -> 4 | AX2: =AV2+AW2 -> 42 | AY2: Playoffs | AZ2: 46186.854 | BA2: 46186 | BB2: 6 | BC2: junio | BD2: 2026
A3: 42500405 | B3: New York | C3: Knicks | D3: 1610612752 | E3: =D3:D2646&A3:A2646 -> 161061275242500405 | F3: San Antonio | G3: Spurs | H3: 1610612759 | I3: =H3:H2646&A3:A2646 -> 161061275942500405 | J3: 0 | K3: 1 | L3: 94 | M3: 90 | N3: 14 | O3: 4 | P3: 8 | Q3: =IF((2*(X3 + 0.44 * AE3))=0,0,L3 / (2*(X3 + 0.44 * AE3))) -> 0.47321788 | R3: =X3 + 0.44 * AE3 - AI3 - AL3 -> 76.32 | S3: =INDEX(X:X,MATCH(I3,E:E,0)) +0.44*INDEX(AE:AE,MATCH(I3,E:E,0)) -INDEX(AI:AI,MATCH(I3,E:E,0)) -INDEX(AL:AL,MATCH(I3,E:E,0)) -> 68.36 | T3: =(L3/R3)*100 -> 123.16562 | U3: =(M3/S3)*100 -> 131.65594 | V3: =T3-U3 -> -8.4903207 | W3: =N3/IF(AL3=0,1,AL3) -> 1.4 | X3: 87 | Y3: 31 | Z3: 0.356 | AA3: 37 | AB3: 12 | AC3: =AB3*3 -> 36 | AD3: 0.324 | AE3: 28 | AF3: 20 | AG3: 0.714 | AH3: 35 | AI3: 13 | AJ3: 48 | AK3: 21 | AL3: 10 | AM3: 4 | AN3: 240 | AO3: 13 | AP3: 24 | AQ3: 28 | AR3: 29 | AS3: 4 | AT3: 13 | AU3: 18 | AV3: 30 | AW3: =L3-(AV3+AC3+AF3) -> 8 | AX3: =AV3+AW3 -> 38 | AY3: Playoffs | AZ3: 46186.854 | BA3: 46186 | BB3: 6 | BC3: junio | BD3: 2026
A4: 42500404 | B4: New York | C4: Knicks | D4: 1610612752 | E4: =D4:D2647&A4:A2647 -> 161061275242500404 | F4: San Antonio | G4: Spurs | H4: 1610612759 | I4: =H4:H2647&A4:A2647 -> 161061275942500404 | J4: 1 | K4: 1 | L4: 107 | M4: 106 | N4: 23 | O4: 4 | P4: 6 | Q4: =IF((2*(X4 + 0.44 * AE4))=0,0,L4 / (2*(X4 + 0.44 * AE4))) -> 0.59233835 | R4: =X4 + 0.44 * AE4 - AI4 - AL4 -> 69.32 | S4: =INDEX(X:X,MATCH(I4,E:E,0)) +0.44*INDEX(AE:AE,MATCH(I4,E:E,0)) -INDEX(AI:AI,MATCH(I4,E:E,0)) -INDEX(AL:AL,MATCH(I4,E:E,0)) -> 71.8 | T4: =(L4/R4)*100 -> 154.35661 | U4: =(M4/S4)*100 -> 147.63231 | V4: =T4-U4 -> 6.7242951 | W4: =N4/IF(AL4=0,1,AL4) -> 1.7692308 | X4: 78 | Y4: 36 | Z4: 0.462 | AA4: 32 | AB4: 15 | AC4: =AB4*3 -> 45 | AD4: 0.469 | AE4: 28 | AF4: 20 | AG4: 0.714 | AH4: 31 | AI4: 8 | AJ4: 39 | AK4: 21 | AL4: 13 | AM4: 1 | AN4: 240 | AO4: 22 | AP4: 27 | AQ4: 26 | AR4: 32 | AS4: 1 | AT4: 13 | AU4: 11 | AV4: 34 | AW4: =L4-(AV4+AC4+AF4) -> 8 | AX4: =AV4+AW4 -> 42 | AY4: Playoffs | AZ4: 46183.854 | BA4: 46183 | BB4: 6 | BC4: junio | BD4: 2026
A5: 42500404 | B5: San Antonio | C5: Spurs | D5: 1610612759 | E5: =D5:D2648&A5:A2648 -> 161061275942500404 | F5: New York | G5: Knicks | H5: 1610612752 | I5: =H5:H2648&A5:A2648 -> 161061275242500404 | J5: 0 | K5: 0 | L5: 106 | M5: 107 | N5: 24 | O5: 4 | P5: 10 | Q5: =IF((2*(X5 + 0.44 * AE5))=0,0,L5 / (2*(X5 + 0.44 * AE5))) -> 0.55907173 | R5: =X5 + 0.44 * AE5 - AI5 - AL5 -> 71.8 | S5: =INDEX(X:X,MATCH(I5,E:E,0)) +0.44*INDEX(AE:AE,MATCH(I5,E:E,0)) -INDEX(AI:AI,MATCH(I5,E:E,0)) -INDEX(AL:AL,MATCH(I5,E:E,0)) -> 69.32 | T5: =(L5/R5)*100 -> 147.63231 | U5: =(M5/S5)*100 -> 154.35661 | V5: =T5-U5 -> -6.7242951 | W5: =N5/IF(AL5=0,1,AL5) -> 2.1818182 | X5: 86 | Y5: 36 | Z5: 0.419 | AA5: 43 | AB5: 17 | AC5: =AB5*3 -> 51 | AD5: 0.395 | AE5: 20 | AF5: 17 | AG5: 0.85 | AH5: 30 | AI5: 12 | AJ5: 42 | AK5: 21 | AL5: 11 | AM5: -1 | AN5: 240 | AO5: 41 | AP5: 35 | AQ5: 14 | AR5: 16 | AS5: 29 | AT5: 12 | AU5: 25 | AV5: 28 | AW5: =L5-(AV5+AC5+AF5) -> 10 | AX5: =AV5+AW5 -> 38 | AY5: Playoffs | AZ5: 46183.854 | BA5: 46183 | BB5: 6 | BC5: junio | BD5: 2026
A6: 42500403 | B6: San Antonio | C6: Spurs | D6: 1610612759 | E6: =D6:D2649&A6:A2649 -> 161061275942500403 | F6: New York | G6: Knicks | H6: 1610612752 | I6: =H6:H2649&A6:A2649 -> 161061275242500403 | J6: 0 | K6: 1 | L6: 115 | M6: 111 | N6: 28 | O6: 7 | P6: 7 | Q6: =IF((2*(X6 + 0.44 * AE6))=0,0,L6 / (2*(X6 + 0.44 * AE6))) -> 0.58625612 | R6: =X6 + 0.44 * AE6 - AI6 - AL6 -> 84.08 | S6: =INDEX(X:X,MATCH(I6,E:E,0)) +0.44*INDEX(AE:AE,MATCH(I6,E:E,0)) -INDEX(AI:AI,MATCH(I6,E:E,0)) -INDEX(AL:AL,MATCH(I6,E:E,0)) -> 72.68 | T6: =(L6/R6)*100 -> 136.7745 | U6: =(M6/S6)*100 -> 152.72427 | V6: =T6-U6 -> -15.94977 | W6: =N6/IF(AL6=0,1,AL6) -> 3.5 | X6: 84 | Y6: 39 | Z6: 0.464 | AA6: 34 | AB6: 12 | AC6: =AB6*3 -> 36 | AD6: 0.353 | AE6: 32 | AF6: 25 | AG6: 0.781 | AH6: 31 | AI6: 6 | AJ6: 37 | AK6: 21 | AL6: 8 | AM6: 4 | AN6: 240 | AO6: 33 | AP6: 24 | AQ6: 35 | AR6: 23 | AS6: 12 | AT6: 5 | AU6: 21 | AV6: 44 | AW6: =L6-(AV6+AC6+AF6) -> 10 | AX6: =AV6+AW6 -> 54 | AY6: Playoffs | AZ6: 46181.854 | BA6: 46181 | BB6: 6 | BC6: junio | BD6: 2026
A7: 42500403 | B7: New York | C7: Knicks | D7: 1610612752 | E7: =D7:D2650&A7:A2650 -> 161061275242500403 | F7: San Antonio | G7: Spurs | H7: 1610612759 | I7: =H7:H2650&A7:A2650 -> 161061275942500403 | J7: 1 | K7: 0 | L7: 111 | M7: 115 | N7: 18 | O7: 6 | P7: 4 | Q7: =IF((2*(X7 + 0.44 * AE7))=0,0,L7 / (2*(X7 + 0.44 * AE7))) -> 0.56818182 | R7: =X7 + 0.44 * AE7 - AI7 - AL7 -> 72.68 | S7: =INDEX(X:X,MATCH(I7,E:E,0)) +0.44*INDEX(AE:AE,MATCH(I7,E:E,0)) -INDEX(AI:AI,MATCH(I7,E:E,0)) -INDEX(AL:AL,MATCH(I7,E:E,0)) -> 84.08 | T7: =(L7/R7)*100 -> 152.72427 | U7: =(M7/S7)*100 -> 136.7745 | V7: =T7-U7 -> 15.94977 | W7: =N7/IF(AL7=0,1,AL7) -> 1.3846154 | X7: 88 | Y7: 40 | Z7: 0.455 | AA7: 37 | AB7: 13 | AC7: =AB7*3 -> 39 | AD7: 0.351 | AE7: 22 | AF7: 18 | AG7: 0.818 | AH7: 34 | AI7: 12 | AJ7: 46 | AK7: 23 | AL7: 13 | AM7: -4 | AN7: 240 | AO7: 22 | AP7: 42 | AQ7: 27 | AR7: 20 | AS7: 7 | AT7: 15 | AU7: 7 | AV7: 46 | AW7: =L7-(AV7+AC7+AF7) -> 8 | AX7: =AV7+AW7 -> 54 | AY7: Playoffs | AZ7: 46181.854 | BA7: 46181 | BB7: 6 | BC7: junio | BD7: 2026
A8: 42500402 | B8: San Antonio | C8: Spurs | D8: 1610612759 | E8: =D8:D2651&A8:A2651 -> 161061275942500402 | F8: New York | G8: Knicks | H8: 1610612752 | I8: =H8:H2651&A8:A2651 -> 161061275242500402 | J8: 1 | K8: 0 | L8: 104 | M8: 105 | N8: 22 | O8: 7 | P8: 7 | Q8: =IF((2*(X8 + 0.44 * AE8))=0,0,L8 / (2*(X8 + 0.44 * AE8))) -> 0.57854918 | R8: =X8 + 0.44 * AE8 - AI8 - AL8 -> 68.88 | S8: =INDEX(X:X,MATCH(I8,E:E,0)) +0.44*INDEX(AE:AE,MATCH(I8,E:E,0)) -INDEX(AI:AI,MATCH(I8,E:E,0)) -INDEX(AL:AL,MATCH(I8,E:E,0)) -> 76.24 | T8: =(L8/R8)*100 -> 150.98722 | U8: =(M8/S8)*100 -> 137.72298 | V8: =T8-U8 -> 13.264244 | W8: =N8/IF(AL8=0,1,AL8) -> 1.375 | X8: 78 | Y8: 37 | Z8: 0.474 | AA8: 29 | AB8: 11 | AC8: =AB8*3 -> 33 | AD8: 0.379 | AE8: 27 | AF8: 19 | AG8: 0.704 | AH8: 37 | AI8: 5 | AJ8: 42 | AK8: 20 | AL8: 16 | AM8: -1 | AN8: 240 | AO8: 34 | AP8: 18 | AQ8: 23 | AR8: 29 | AS8: 12 | AT8: 11 | AU8: 19 | AV8: 48 | AW8: =L8-(AV8+AC8+AF8) -> 4 | AX8: =AV8+AW8 -> 52 | AY8: Playoffs | AZ8: 46178.854 | BA8: 46178 | BB8: 6 | BC8: junio | BD8: 2026
A9: 42500402 | B9: New York | C9: Knicks | D9: 1610612752 | E9: =D9:D2652&A9:A2652 -> 161061275242500402 | F9: San Antonio | G9: Spurs | H9: 1610612759 | I9: =H9:H2652&A9:A2652 -> 161061275942500402 | J9: 0 | K9: 1 | L9: 105 | M9: 104 | N9: 29 | O9: 6 | P9: 11 | Q9: =IF((2*(X9 + 0.44 * AE9))=0,0,L9 / (2*(X9 + 0.44 * AE9))) -> 0.53440554 | R9: =X9 + 0.44 * AE9 - AI9 - AL9 -> 76.24 | S9: =INDEX(X:X,MATCH(I9,E:E,0)) +0.44*INDEX(AE:AE,MATCH(I9,E:E,0)) -INDEX(AI:AI,MATCH(I9,E:E,0)) -INDEX(AL:AL,MATCH(I9,E:E,0)) -> 68.88 | T9: =(L9/R9)*100 -> 137.72298 | U9: =(M9/S9)*100 -> 150.98722 | V9: =T9-U9 -> -13.264244 | W9: =N9/IF(AL9=0,1,AL9) -> 2.4166667 | X9: 89 | Y9: 37 | Z9: 0.416 | AA9: 38 | AB9: 15 | AC9: =AB9*3 -> 45 | AD9: 0.395 | AE9: 21 | AF9: 16 | AG9: 0.762 | AH9: 34 | AI9: 10 | AJ9: 44 | AK9: 23 | AL9: 12 | AM9: 1 | AN9: 240 | AO9: 25 | AP9: 31 | AQ9: 28 | AR9: 21 | AS9: 14 | AT9: 19 | AU9: 16 | AV9: 38 | AW9: =L9-(AV9+AC9+AF9) -> 6 | AX9: =AV9+AW9 -> 44 | AY9: Playoffs | AZ9: 46178.854 | BA9: 46178 | BB9: 6 | BC9: junio | BD9: 2026
A10: 42500401 | B10: San Antonio | C10: Spurs | D10: 1610612759 | E10: =D10:D2653&A10:A2653 -> 161061275942500401 | F10: New York | G10: Knicks | H10: 1610612752 | I10: =H10:H2653&A10:A2653 -> 161061275242500401 | J10: 1 | K10: 0 | L10: 95 | M10: 105 | N10: 16 | O10: 4 | P10: 4 | Q10: =IF((2*(X10 + 0.44 * AE10))=0,0,L10 / (2*(X10 + 0.44 * AE10))) -> 0.475 | R10: =X10 + 0.44 * AE10 - AI10 - AL10 -> 73 | S10: =INDEX(X:X,MATCH(I10,E:E,0)) +0.44*INDEX(AE:AE,MATCH(I10,E:E,0)) -INDEX(AI:AI,MATCH(I10,E:E,0)) -INDEX(AL:AL,MATCH(I10,E:E,0)) -> 83.92 | T10: =(L10/R10)*100 -> 130.13699 | U10: =(M10/S10)*100 -> 125.11916 | V10: =T10-U10 -> 5.0178252 | W10: =N10/IF(AL10=0,1,AL10) -> 1.2307692 | X10: 89 | Y10: 32 | Z10: 0.36 | AA10: 43 | AB10: 11 | AC10: =AB10*3 -> 33 | AD10: 0.256 | AE10: 25 | AF10: 20 | AG10: 0.8 | AH10: 40 | AI10: 14 | AJ10: 54 | AK10: 23 | AL10: 13 | AM10: -10 | AN10: 240 | AO10: 27 | AP10: 28 | AQ10: 21 | AR10: 19 | AS10: 14 | AT10: 15 | AU10: 14 | AV10: 42 | AW10: =L10-(AV10+AC10+AF10) -> 0 | AX10: =AV10+AW10 -> 42 | AY10: Playoffs | AZ10: 46176.854 | BA10: 46176 | BB10: 6 | BC10: junio | BD10: 2026
A11: 42500401 | B11: New York | C11: Knicks | D11: 1610612752 | E11: =D11:D2654&A11:A2654 -> 161061275242500401 | F11: San Antonio | G11: Spurs | H11: 1610612759 | I11: =H11:H2654&A11:A2654 -> 161061275942500401 | J11: 0 | K11: 1 | L11: 105 | M11: 95 | N11: 20 | O11: 4 | P11: 8 | Q11: =IF((2*(X11 + 0.44 * AE11))=0,0,L11 / (2*(X11 + 0.44 * AE11))) -> 0.51510989 | R11: =X11 + 0.44 * AE11 - AI11 - AL11 -> 83.92 | S11: =INDEX(X:X,MATCH(I11,E:E,0)) +0.44*INDEX(AE:AE,MATCH(I11,E:E,0)) -INDEX(AI:AI,MATCH(I11,E:E,0)) -INDEX(AL:AL,MATCH(I11,E:E,0)) -> 73 | T11: =(L11/R11)*100 -> 125.11916 | U11: =(M11/S11)*100 -> 130.13699 | V11: =T11-U11 -> -5.0178252 | W11: =N11/IF(AL11=0,1,AL11) -> 2.5 | X11: 94 | Y11: 39 | Z11: 0.415 | AA11: 36 | AB11: 11 | AC11: =AB11*3 -> 33 | AD11: 0.306 | AE11: 18 | AF11: 16 | AG11: 0.889 | AH11: 39 | AI11: 10 | AJ11: 49 | AK11: 23 | AL11: 8 | AM11: 10 | AN11: 240 | AO11: 19 | AP11: 29 | AQ11: 28 | AR11: 29 | AS11: 10 | AT11: 12 | AU11: 19 | AV11: 50 | AW11: =L11-(AV11+AC11+AF11) -> 6 | AX11: =AV11+AW11 -> 56 | AY11: Playoffs | AZ11: 46176.854 | BA11: 46176 | BB11: 6 | BC11: junio | BD11: 2026
A12: 42500317 | B12: San Antonio | C12: Spurs | D12: 1610612759 | E12: =D12:D2655&A12:A2655 -> 161061275942500317 | F12: Oklahoma City | G12: Thunder | H12: 1610612760 | I12: =H12:H2655&A12:A2655 -> 161061276042500317 | J12: 0 | K12: 1 | L12: 111 | M12: 103 | N12: 21 | O12: 2 | P12: 9 | Q12: =IF((2*(X12 + 0.44 * AE12))=0,0,L12 / (2*(X12 + 0.44 * AE12))) -> 0.57596513 | R12: =X12 + 0.44 * AE12 - AI12 - AL12 -> 69.36 | S12: =INDEX(X:X,MATCH(I12,E:E,0)) +0.44*INDEX(AE:AE,MATCH(I12,E:E,0)) -INDEX(AI:AI,MATCH(I12,E:E,0)) -INDEX(AL:AL,MATCH(I12,E:E,0)) -> 69.68 | T12: =(L12/R12)*100 -> 160.0346 | U12: =(M12/S12)*100 -> 147.8186 | V12: =T12-U12 -> 12.216003 | W12: =N12/IF(AL12=0,1,AL12) -> 1.75 | X12: 88 | Y12: 40 | Z12: 0.455 | AA12: 40 | AB12: 17 | AC12: =AB12*3 -> 51 | AD12: 0.425 | AE12: 19 | AF12: 14 | AG12: 0.737 | AH12: 25 | AI12: 15 | AJ12: 40 | AK12: 18 | AL12: 12 | AM12: 8 | AN12: 240 | AO12: 32 | AP12: 24 | AQ12: 24 | AR12: 31 | AS12: 14 | AT12: 19 | AU12: 19 | AV12: 34 | AW12: =L12-(AV12+AC12+AF12) -> 12 | AX12: =AV12+AW12 -> 46 | AY12: Playoffs | AZ12: 46172.833 | BA12: 46172 | BB12: 5 | BC12: mayo | BD12: 2026
A13: 42500317 | B13: Oklahoma City | C13: Thunder | D13: 1610612760 | E13: =D13:D2656&A13:A2656 -> 161061276042500317 | F13: San Antonio | G13: Spurs | H13: 1610612759 | I13: =H13:H2656&A13:A2656 -> 161061275942500317 | J13: 1 | K13: 0 | L13: 103 | M13: 111 | N13: 23 | O13: 5 | P13: 9 | Q13: =IF((2*(X13 + 0.44 * AE13))=0,0,L13 / (2*(X13 + 0.44 * AE13))) -> 0.55567544 | R13: =X13 + 0.44 * AE13 - AI13 - AL13 -> 69.68 | S13: =INDEX(X:X,MATCH(I13,E:E,0)) +0.44*INDEX(AE:AE,MATCH(I13,E:E,0)) -INDEX(AI:AI,MATCH(I13,E:E,0)) -INDEX(AL:AL,MATCH(I13,E:E,0)) -> 69.36 | T13: =(L13/R13)*100 -> 147.8186 | U13: =(M13/S13)*100 -> 160.0346 | V13: =T13-U13 -> -12.216003 | W13: =N13/IF(AL13=0,1,AL13) -> 1.7692308 | X13: 83 | Y13: 37 | Z13: 0.446 | AA13: 35 | AB13: 12 | AC13: =AB13*3 -> 36 | AD13: 0.343 | AE13: 22 | AF13: 17 | AG13: 0.773 | AH13: 28 | AI13: 10 | AJ13: 38 | AK13: 16 | AL13: 13 | AM13: -8 | AN13: 240 | AO13: 25 | AP13: 28 | AQ13: 24 | AR13: 26 | AS13: 4 | AT13: 7 | AU13: 9 | AV13: 32 | AW13: =L13-(AV13+AC13+AF13) -> 18 | AX13: =AV13+AW13 -> 50 | AY13: Playoffs | AZ13: 46172.833 | BA13: 46172 | BB13: 5 | BC13: mayo | BD13: 2026
... A2645: 22500001 | B2645: Houston | C2645: Rockets | D2645: 1610612745 | E2645: =D2645:D5288&A2645:A5288 -> 161061274522500001 | F2645: Oklahoma City | G2645: Thunder | H2645: 1610612760 | I2645: =H2645:H5288&A2645:A5288 -> 161061276022500001 | J2645: 0 | K2645: 0 | L2645: 124 | M2645: 125 | N2645: 23 | O2645: 5 | P2645: 6 | Q2645: =IF((2*(X2645 + 0.44 * AE2645))=0,0,L2645 / (2*(X2645 + 0.44 * AE2645))) -> 0.56037599 | R2645: =X2645 + 0.44 * AE2645 - AI2645 - AL2645 -> 72.64 | S2645: =INDEX(X:X,MATCH(I2645,E:E,0)) +0.44*INDEX(AE:AE,MATCH(I2645,E:E,0)) -INDEX(AI:AI,MATCH(I2645,E:E,0)) -INDEX(AL:AL,MATCH(I2645,E:E,0)) -> 93 | T2645: =(L2645/R2645)*100 -> 170.70485 | U2645: =(M2645/S2645)*100 -> 134.4086 | V2645: =T2645-U2645 -> 36.296244 | W2645: =N2645/IF(AL2645=0,1,AL2645) -> 1.0454545 | X2645: 97 | Y2645: 43 | Z2645: 0.443 | AA2645: 39 | AB2645: 11 | AC2645: =AB2645*3 -> 33 | AD2645: 0.282 | AE2645: 31 | AF2645: 27 | AG2645: 0.871 | AH2645: 36 | AI2645: 16 | AJ2645: 52 | AK2645: 26 | AL2645: 22 | AM2645: -1 | AN2645: 290 | AO2645: 30 | AP2645: 27 | AQ2645: 22 | AR2645: 25 | AS2645: 12 | AT2645: 2 | AU2645: 12 | AV2645: 44 | AW2645: =L2645-(AV2645+AC2645+AF2645) -> 20 | AX2645: =AV2645+AW2645 -> 64 | AY2645: Regular Season | AZ2645: 45951.812 | BA2645: 45951 | BB2645: 10 | BC2645: octubre | BD2645: 2025

Sheet KPI's
A1: Puntos por partido | B1: Puntos en el 1er cuarto | C1: Puntos en el 2do cuarto | D1: Puntos en el 3er cuarto | E1: Puntos en el 4to cuarto
A2: 112.21591 | B2: 28.943182 | C2: 28.920455 | D2: 28.193182 | E2: 25.852273
A4: Puntos por partido | B4: Puntos en el 1er cuarto | C4: Puntos en el 2do cuarto | D4: Puntos en el 3er cuarto | E4: Puntos en el 4to cuarto
A5: =A2 -> 112.21591 | B5: =B2 -> 28.943182 | C5: =C2 -> 28.920455 | D5: =D2 -> 28.193182 | E5: =E2 -> 25.852273
A7: Promedio de teamScore | B7: Promedio de assists | C7: Promedio de fieldGoalsPercentage | D7: Promedio de threePointersPercentage | E7: Promedio de freeThrowsPercentage
A8: 112.21591 | B8: 24.454545 | C8: 0.45626136 | D8: 0.35935227 | E8: 0.776375
A10: Puntos por partido | B10: Puntos en el 1er cuarto | C10: Puntos en el 2do cuarto | D10: Puntos en el 3er cuarto | E10: Puntos en el 4to cuarto
A11: =A8 -> 112.21591 | B11: =B8 -> 24.454545 | C11: =C8 -> 0.45626136 | D11: =D8 -> 0.35935227 | E11: =E8 -> 0.776375

Sheet Análisis_Influencia_estadística
B1: Derrota VS Victoria
A2: Valores | B2: 0 | C2: 1 | E2: Jerarquía | F2: Promedio | G2: Victoria | H2: Derrota | I2: Relación general
A3: Promedio de teamScore | B3: 105.09524 | C3: 118.71739 | E3: =RANK(G3,$G$3:$G$12) -> 4 | F3: Puntos Anotados | G3: =C3/(B3+C3) -> 0.53043205 | H3: =1-G3 -> 0.46956795 | I3: Directa Consistente
A4: Promedio de assists | B4: 22.238095 | C4: 26.478261 | E4: =RANK(G4,$G$3:$G$12) -> 2 | F4: Asistencias | G4: =C4/(B4+C4) -> 0.54351891 | H4: =1-G4 -> 0.45648109 | I4: Directa Fuerte
A5: Promedio de blocks | B5: 3.9047619 | C5: 4.4347826 | E5: =RANK(G5,$G$3:$G$12) -> 3 | F5: Tapones | G5: =C5/(B5+C5) -> 0.53177756 | H5: =1-G5 -> 0.46822244 | I5: Directa Fuerte
A6: Promedio de steals | B6: 8.8809524 | C6: 9.9130435 | E6: =RANK(G6,$G$3:$G$12) -> 5 | F6: Robos | G6: =C6/(B6+C6) -> 0.527458 | H6: =1-G6 -> 0.472542 | I6: Directa Fuerte
A7: Promedio de reboundsDefensive | B7: 28.380952 | C7: 31.478261 | E7: =RANK(G7,$G$3:$G$12) -> 6 | F7: Rebotes Defensivos | G7: =C7/(B7+C7) -> 0.52587161 | H7: =1-G7 -> 0.47412839 | I7: Directa Consistente
A8: Promedio de reboundsOffensive | B8: 12.333333 | C8: 13.304348 | E8: =RANK(G8,$G$3:$G$12) -> 8 | F8: Rebotes Ofensivos | G8: =C8/(B8+C8) -> 0.51893725 | H8: =1-G8 -> 0.48106275 | I8: Neutra
A9: Promedio de reboundsTotal | B9: 40.714286 | C9: 44.782609 | E9: =RANK(G9,$G$3:$G$12) -> 7 | F9: Rebotes Totales | G9: =C9/(B9+C9) -> 0.52379223 | H9: =1-G9 -> 0.47620777 | I9: Directa Consistente
A10: Promedio de foulsPersonal | B10: 21.238095 | C10: 20.413043 | E10: =RANK(G10,$G$3:$G$12) -> 10 | F10: Faltas personales | G10: =C10/(B10+C10) -> 0.49009569 | H10: =1-G10 -> 0.50990431 | I10: Inversa
A11: Promedio de turnovers | B11: 13.785714 | C11: 13.413043 | E11: =RANK(G11,$G$3:$G$12) -> 9 | F11: Pérdidas de balón | G11: =C11/(B11+C11) -> 0.49314912 | H11: =1-G11 -> 0.50685088 | I11: Inversa
A12: Suma de home | B12: 19 | C12: 26 | E12: =RANK(G12,$G$3:$G$12) -> 1 | F12: Jugar en casa | G12: =C12/(B12+C12) -> 0.57777778 | H12: =1-G12 -> 0.42222222 | I12: Directa Fuerte
E14: Jerarquía | F14: Promedio | G14: Victoria | H14: Derrota | I14: Relación
E15: 10 | F15: =VLOOKUP(E15,$E$3:$I$12,2,0) -> Faltas personales | G15: =VLOOKUP(E15,$E$3:$I$12,3,0) -> 0.49009569 | H15: =VLOOKUP(E15,$E$3:$I$12,4,0) -> 0.50990431 | I15: =VLOOKUP(E15,$E$3:$I$12,5,0) -> Inversa
E16: 9 | F16: =VLOOKUP(E16,$E$3:$I$12,2,0) -> Pérdidas de balón | G16: =VLOOKUP(E16,$E$3:$I$12,3,0) -> 0.49314912 | H16: =VLOOKUP(E16,$E$3:$I$12,4,0) -> 0.50685088 | I16: =VLOOKUP(E16,$E$3:$I$12,5,0) -> Inversa
E17: 8 | F17: =VLOOKUP(E17,$E$3:$I$12,2,0) -> Rebotes Ofensivos | G17: =VLOOKUP(E17,$E$3:$I$12,3,0) -> 0.51893725 | H17: =VLOOKUP(E17,$E$3:$I$12,4,0) -> 0.48106275 | I17: =VLOOKUP(E17,$E$3:$I$12,5,0) -> Neutra
E18: 7 | F18: =VLOOKUP(E18,$E$3:$I$12,2,0) -> Rebotes Totales | G18: =VLOOKUP(E18,$E$3:$I$12,3,0) -> 0.52379223 | H18: =VLOOKUP(E18,$E$3:$I$12,4,0) -> 0.47620777 | I18: =VLOOKUP(E18,$E$3:$I$12,5,0) -> Directa Consistente
E19: 6 | F19: =VLOOKUP(E19,$E$3:$I$12,2,0) -> Rebotes Defensivos | G19: =VLOOKUP(E19,$E$3:$I$12,3,0) -> 0.52587161 | H19: =VLOOKUP(E19,$E$3:$I$12,4,0) -> 0.47412839 | I19: =VLOOKUP(E19,$E$3:$I$12,5,0) -> Directa Consistente
E20: 5 | F20: =VLOOKUP(E20,$E$3:$I$12,2,0) -> Robos | G20: =VLOOKUP(E20,$E$3:$I$12,3,0) -> 0.527458 | H20: =VLOOKUP(E20,$E$3:$I$12,4,0) -> 0.472542 | I20: =VLOOKUP(E20,$E$3:$I$12,5,0) -> Directa Fuerte
E21: 4 | F21: =VLOOKUP(E21,$E$3:$I$12,2,0) -> Puntos Anotados | G21: =VLOOKUP(E21,$E$3:$I$12,3,0) -> 0.53043205 | H21: =VLOOKUP(E21,$E$3:$I$12,4,0) -> 0.46956795 | I21: =VLOOKUP(E21,$E$3:$I$12,5,0) -> Directa Consistente
E22: 3 | F22: =VLOOKUP(E22,$E$3:$I$12,2,0) -> Tapones | G22: =VLOOKUP(E22,$E$3:$I$12,3,0) -> 0.53177756 | H22: =VLOOKUP(E22,$E$3:$I$12,4,0) -> 0.46822244 | I22: =VLOOKUP(E22,$E$3:$I$12,5,0) -> Directa Fuerte
E23: 2 | F23: =VLOOKUP(E23,$E$3:$I$12,2,0) -> Asistencias | G23: =VLOOKUP(E23,$E$3:$I$12,3,0) -> 0.54351891 | H23: =VLOOKUP(E23,$E$3:$I$12,4,0) -> 0.45648109 | I23: =VLOOKUP(E23,$E$3:$I$12,5,0) -> Directa Fuerte
E24: 1 | F24: =VLOOKUP(E24,$E$3:$I$12,2,0) -> Jugar en casa | G24: =VLOOKUP(E24,$E$3:$I$12,3,0) -> 0.57777778 | H24: =VLOOKUP(E24,$E$3:$I$12,4,0) -> 0.42222222 | I24: =VLOOKUP(E24,$E$3:$I$12,5,0) -> Directa Fuerte

Sheet Análisis_lanzamientos
A1: teamgameId | B1: teamScore | C1: threePointers | D1: freeThrowsMade | E1: PointsInTheArea | F1: MEDIANA ÁREA FIJA | G1: Puntos de triple | H1: Puntos en área | I1: ↖ T<39 A>=56 | J1: ↗ T>=39 A>=56 | K1: ↙ T<39 A<56 | L1: ↘ T>=39 A<56 | R1: Máximo/Mínimo | S1: maxthreePointers | T1: minthreePointers | U1: maxPointsInTheArea | V1: minPointsInTheArea
A2: 161061275622500025 | B2: 118 | C2: 51 | D2: 15 | E2: 52 | F2: 56 | G2: =IF(C2="",NA(),C2) -> 51 | H2: =IF(E2="",NA(),E2) -> 52 | I2: =IF(ISNUMBER(G2),IF( (G2>=$F$4)*(H2<$F$2),G2, NA() ),NA()) -> 51 | J2: =IF(ISNUMBER(G2),IF( (G2>=$F$4)*(H2>=$F$2),G2, NA() ),NA()) -> #N/A | K2: =IF(ISNUMBER(G2),IF( (G2<$F$4)*(H2<$F$2),G2, NA() ),NA()) -> #N/A | L2: =IF(ISNUMBER(G2),IF( (G2<$F$4)*(H2>=$F$2),G2, NA() ),NA()) -> #N/A | R2: 76ers | S2: 66 | T2: 9 | U2: 90 | V2: 36
A3: 161061275622500053 | B3: 114 | C3: 42 | D3: 22 | E3: 50 | F3: MEDIANA TRIPLES FIJA | G3: =IF(C3="",NA(),C3) -> 42 | H3: =IF(E3="",NA(),E3) -> 50 | I3: =IF(ISNUMBER(G3),IF( (G3>=$F$4)*(H3<$F$2),G3, NA() ),NA()) -> 42 | J3: =IF(ISNUMBER(G3),IF( (G3>=$F$4)*(H3>=$F$2),G3, NA() ),NA()) -> #N/A | K3: =IF(ISNUMBER(G3),IF( (G3<$F$4)*(H3<$F$2),G3, NA() ),NA()) -> #N/A | L3: =IF(ISNUMBER(G3),IF( (G3<$F$4)*(H3>=$F$2),G3, NA() ),NA()) -> #N/A | R3: Bucks | S3: 72 | T3: 24 | U3: 80 | V3: 28
A4: 161061275622500068 | B4: 112 | C4: 42 | D4: 14 | E4: 56 | F4: 39 | G4: =IF(C4="",NA(),C4) -> 42 | H4: =IF(E4="",NA(),E4) -> 56 | I4: =IF(ISNUMBER(G4),IF( (G4>=$F$4)*(H4<$F$2),G4, NA() ),NA()) -> #N/A | J4: =IF(ISNUMBER(G4),IF( (G4>=$F$4)*(H4>=$F$2),G4, NA() ),NA()) -> 42 | K4: =IF(ISNUMBER(G4),IF( (G4<$F$4)*(H4<$F$2),G4, NA() ),NA()) -> #N/A | L4: =IF(ISNUMBER(G4),IF( (G4<$F$4)*(H4>=$F$2),G4, NA() ),NA()) -> #N/A | R4: Bulls | S4: 75 | T4: 18 | U4: 84 | V4: 36
A5: 161061275622500075 | B5: 119 | C5: 45 | D5: 20 | E5: 54 | G5: =IF(C5="",NA(),C5) -> 45 | H5: =IF(E5="",NA(),E5) -> 54 | I5: =IF(ISNUMBER(G5),IF( (G5>=$F$4)*(H5<$F$2),G5, NA() ),NA()) -> 45 | J5: =IF(ISNUMBER(G5),IF( (G5>=$F$4)*(H5>=$F$2),G5, NA() ),NA()) -> #N/A | K5: =IF(ISNUMBER(G5),IF( (G5<$F$4)*(H5<$F$2),G5, NA() ),NA()) -> #N/A | L5: =IF(ISNUMBER(G5),IF( (G5<$F$4)*(H5>=$F$2),G5, NA() ),NA()) -> #N/A | R5: Cavaliers | S5: 72 | T5: 18 | U5: 84 | V5: 36
A6: 161061275622500088 | B6: 120 | C6: 30 | D6: 20 | E6: 70 | F6: MEDIANA ÁREA DINÁMICA | G6: =IF(C6="",NA(),C6) -> 30 | H6: =IF(E6="",NA(),E6) -> 70 | I6: =IF(ISNUMBER(G6),IF( (G6>=$F$4)*(H6<$F$2),G6, NA() ),NA()) -> #N/A | J6: =IF(ISNUMBER(G6),IF( (G6>=$F$4)*(H6>=$F$2),G6, NA() ),NA()) -> #N/A | K6: =IF(ISNUMBER(G6),IF( (G6<$F$4)*(H6<$F$2),G6, NA() ),NA()) -> #N/A | L6: =IF(ISNUMBER(G6),IF( (G6<$F$4)*(H6>=$F$2),G6, NA() ),NA()) -> 30 | R6: Celtics | S6: 87 | T6: 21 | U6: 78 | V6: 32
A7: 161061275622500099 | B7: 102 | C7: 48 | D7: 12 | E7: 42 | F7: =MEDIAN(E7:E2650) -> 50 | G7: =IF(C7="",NA(),C7) -> 48 | H7: =IF(E7="",NA(),E7) -> 42 | I7: =IF(ISNUMBER(G7),IF( (G7>=$F$4)*(H7<$F$2),G7, NA() ),NA()) -> 48 | J7: =IF(ISNUMBER(G7),IF( (G7>=$F$4)*(H7>=$F$2),G7, NA() ),NA()) -> #N/A | K7: =IF(ISNUMBER(G7),IF( (G7<$F$4)*(H7<$F$2),G7, NA() ),NA()) -> #N/A | L7: =IF(ISNUMBER(G7),IF( (G7<$F$4)*(H7>=$F$2),G7, NA() ),NA()) -> #N/A | R7: Clippers | S7: 63 | T7: 12 | U7: 74 | V7: 30
A8: 161061275622500104 | B8: 111 | C8: 51 | D8: 18 | E8: 42 | F8: MEDIANA TRIPLES DINÁMICA | G8: =IF(C8="",NA(),C8) -> 51 | H8: =IF(E8="",NA(),E8) -> 42 | I8: =IF(ISNUMBER(G8),IF( (G8>=$F$4)*(H8<$F$2),G8, NA() ),NA()) -> 51 | J8: =IF(ISNUMBER(G8),IF( (G8>=$F$4)*(H8>=$F$2),G8, NA() ),NA()) -> #N/A | K8: =IF(ISNUMBER(G8),IF( (G8<$F$4)*(H8<$F$2),G8, NA() ),NA()) -> #N/A | L8: =IF(ISNUMBER(G8),IF( (G8<$F$4)*(H8>=$F$2),G8, NA() ),NA()) -> #N/A | R8: Grizzlies | S8: 87 | T8: 21 | U8: 80 | V8: 32
A9: 161061275622500120 | B9: 134 | C9: 60 | D9: 24 | E9: 50 | F9: =MEDIAN(C7:C2650) -> 45 | G9: =IF(C9="",NA(),C9) -> 60 | H9: =IF(E9="",NA(),E9) -> 50 | I9: =IF(ISNUMBER(G9),IF( (G9>=$F$4)*(H9<$F$2),G9, NA() ),NA()) -> 60 | J9: =IF(ISNUMBER(G9),IF( (G9>=$F$4)*(H9>=$F$2),G9, NA() ),NA()) -> #N/A | K9: =IF(ISNUMBER(G9),IF( (G9<$F$4)*(H9<$F$2),G9, NA() ),NA()) -> #N/A | L9: =IF(ISNUMBER(G9),IF( (G9<$F$4)*(H9>=$F$2),G9, NA() ),NA()) -> #N/A | R9: Hawks | S9: 75 | T9: 18 | U9: 82 | V9: 38
A10: 161061275622500137 | B10: 113 | C10: 48 | D10: 15 | E10: 50 | G10: =IF(C10="",NA(),C10) -> 48 | H10: =IF(E10="",NA(),E10) -> 50 | I10: =IF(ISNUMBER(G10),IF( (G10>=$F$4)*(H10<$F$2),G10, NA() ),NA()) -> 48 | J10: =IF(ISNUMBER(G10),IF( (G10>=$F$4)*(H10>=$F$2),G10, NA() ),NA()) -> #N/A | K10: =IF(ISNUMBER(G10),IF( (G10<$F$4)*(H10<$F$2),G10, NA() ),NA()) -> #N/A | L10: =IF(ISNUMBER(G10),IF( (G10<$F$4)*(H10>=$F$2),G10, NA() ),NA()) -> #N/A | R10: Heat | S10: 72 | T10: 12 | U10: 86 | V10: 36
A11: 161061275622500154 | B11: 130 | C11: 57 | D11: 19 | E11: 54 | G11: =IF(C11="",NA(),C11) -> 57 | H11: =IF(E11="",NA(),E11) -> 54 | I11: =IF(ISNUMBER(G11),IF( (G11>=$F$4)*(H11<$F$2),G11, NA() ),NA()) -> 57 | J11: =IF(ISNUMBER(G11),IF( (G11>=$F$4)*(H11>=$F$2),G11, NA() ),NA()) -> #N/A | K11: =IF(ISNUMBER(G11),IF( (G11<$F$4)*(H11<$F$2),G11, NA() ),NA()) -> #N/A | L11: =IF(ISNUMBER(G11),IF( (G11<$F$4)*(H11>=$F$2),G11, NA() ),NA()) -> #N/A | R11: Hornets | S11: 78 | T11: 24 | U11: 70 | V11: 28
A12: 161061275622500169 | B12: 107 | C12: 36 | D12: 15 | E12: 56 | G12: =IF(C12="",NA(),C12) -> 36 | H12: =IF(E12="",NA(),E12) -> 56 | I12: =IF(ISNUMBER(G12),IF( (G12>=$F$4)*(H12<$F$2),G12, NA() ),NA()) -> #N/A | J12: =IF(ISNUMBER(G12),IF( (G12>=$F$4)*(H12>=$F$2),G12, NA() ),NA()) -> #N/A | K12: =IF(ISNUMBER(G12),IF( (G12<$F$4)*(H12<$F$2),G12, NA() ),NA()) -> #N/A | L12: =IF(ISNUMBER(G12),IF( (G12<$F$4)*(H12>=$F$2),G12, NA() ),NA()) -> 36 | R12: Jazz | S12: 57 | T12: 15 | U12: 94 | V12: 36
A13: 161061275622500182 | B13: 115 | C13: 57 | D13: 14 | E13: 44 | G13: =IF(C13="",NA(),C13) -> 57 | H13: =IF(E13="",NA(),E13) -> 44 | I13: =IF(ISNUMBER(G13),IF( (G13>=$F$4)*(H13<$F$2),G13, NA() ),NA()) -> 57 | J13: =IF(ISNUMBER(G13),IF( (G13>=$F$4)*(H13>=$F$2),G13, NA() ),NA()) -> #N/A | K13: =IF(ISNUMBER(G13),IF( (G13<$F$4)*(H13<$F$2),G13, NA() ),NA()) -> #N/A | L13: =IF(ISNUMBER(G13),IF( (G13<$F$4)*(H13>=$F$2),G13, NA() ),NA()) -> #N/A | R13: Kings | S13: 54 | T13: 12 | U13: 86 | V13: 42
A14: 161061275622500190 | B14: 114 | C14: 48 | D14: 18 | E14: 48 | G14: =IF(C14="",NA(),C14) -> 48 | H14: =IF(E14="",NA(),E14) -> 48 | I14: =IF(ISNUMBER(G14),IF( (G14>=$F$4)*(H14<$F$2),G14, NA() ),NA()) -> 48 | J14: =IF(ISNUMBER(G14),IF( (G14>=$F$4)*(H14>=$F$2),G14, NA() ),NA()) -> #N/A | K14: =IF(ISNUMBER(G14),IF( (G14<$F$4)*(H14<$F$2),G14, NA() ),NA()) -> #N/A | L14: =IF(ISNUMBER(G14),IF( (G14<$F$4)*(H14>=$F$2),G14, NA() ),NA()) -> #N/A | R14: Knicks | S14: 75 | T14: 21 | U14: 88 | V14: 32
A15: 161061275622500204 | B15: 121 | C15: 57 | D15: 24 | E15: 40 | G15: =IF(C15="",NA(),C15) -> 57 | H15: =IF(E15="",NA(),E15) -> 40 | I15: =IF(ISNUMBER(G15),IF( (G15>=$F$4)*(H15<$F$2),G15, NA() ),NA()) -> 57 | J15: =IF(ISNUMBER(G15),IF( (G15>=$F$4)*(H15>=$F$2),G15, NA() ),NA()) -> #N/A | K15: =IF(ISNUMBER(G15),IF( (G15<$F$4)*(H15<$F$2),G15, NA() ),NA()) -> #N/A | L15: =IF(ISNUMBER(G15),IF( (G15<$F$4)*(H15>=$F$2),G15, NA() ),NA()) -> #N/A | R15: Lakers | S15: 57 | T15: 15 | U15: 82 | V15: 38
A16: 161061275622500221 | B16: 123 | C16: 42 | D16: 21 | E16: 60 | G16: =IF(C16="",NA(),C16) -> 42 | H16: =IF(E16="",NA(),E16) -> 60 | I16: =IF(ISNUMBER(G16),IF( (G16>=$F$4)*(H16<$F$2),G16, NA() ),NA()) -> #N/A | J16: =IF(ISNUMBER(G16),IF( (G16>=$F$4)*(H16>=$F$2),G16, NA() ),NA()) -> 42 | K16: =IF(ISNUMBER(G16),IF( (G16<$F$4)*(H16<$F$2),G16, NA() ),NA()) -> #N/A | L16: =IF(ISNUMBER(G16),IF( (G16<$F$4)*(H16>=$F$2),G16, NA() ),NA()) -> #N/A | R16: Magic | S16: 81 | T16: 9 | U16: 82 | V16: 30
A17: 161061275622500226 | B17: 133 | C17: 39 | D17: 22 | E17: 72 | G17: =IF(C17="",NA(),C17) -> 39 | H17: =IF(E17="",NA(),E17) -> 72 | I17: =IF(ISNUMBER(G17),IF( (G17>=$F$4)*(H17<$F$2),G17, NA() ),NA()) -> #N/A | J17: =IF(ISNUMBER(G17),IF( (G17>=$F$4)*(H17>=$F$2),G17, NA() ),NA()) -> 39 | K17: =IF(ISNUMBER(G17),IF( (G17<$F$4)*(H17<$F$2),G17, NA() ),NA()) -> #N/A | L17: =IF(ISNUMBER(G17),IF( (G17<$F$4)*(H17>=$F$2),G17, NA() ),NA()) -> #N/A | R17: Mavericks | S17: 66 | T17: 9 | U17: 90 | V17: 36
A18: 161061275622500239 | B18: 122 | C18: 30 | D18: 18 | E18: 74 | G18: =IF(C18="",NA(),C18) -> 30 | H18: =IF(E18="",NA(),E18) -> 74 | I18: =IF(ISNUMBER(G18),IF( (G18>=$F$4)*(H18<$F$2),G18, NA() ),NA()) -> #N/A | J18: =IF(ISNUMBER(G18),IF( (G18>=$F$4)*(H18>=$F$2),G18, NA() ),NA()) -> #N/A | K18: =IF(ISNUMBER(G18),IF( (G18<$F$4)*(H18<$F$2),G18, NA() ),NA()) -> #N/A | L18: =IF(ISNUMBER(G18),IF( (G18<$F$4)*(H18>=$F$2),G18, NA() ),NA()) -> 30 | R18: Nets | S18: 57 | T18: 18 | U18: 74 | V18: 24
A19: 161061275622500254 | B19: 127 | C19: 42 | D19: 19 | E19: 66 | G19: =IF(C19="",NA(),C19) -> 42 | H19: =IF(E19="",NA(),E19) -> 66 | I19: =IF(ISNUMBER(G19),IF( (G19>=$F$4)*(H19<$F$2),G19, NA() ),NA()) -> #N/A | J19: =IF(ISNUMBER(G19),IF( (G19>=$F$4)*(H19>=$F$2),G19, NA() ),NA()) -> 42 | K19: =IF(ISNUMBER(G19),IF( (G19<$F$4)*(H19<$F$2),G19, NA() ),NA()) -> #N/A | L19: =IF(ISNUMBER(G19),IF( (G19<$F$4)*(H19>=$F$2),G19, NA() ),NA()) -> #N/A | R19: Nuggets | S19: 72 | T19: 18 | U19: 80 | V19: 38
A20: 161061275622500281 | B20: 111 | C20: 42 | D20: 11 | E20: 58 | G20: =IF(C20="",NA(),C20) -> 42 | H20: =IF(E20="",NA(),E20) -> 58 | I20: =IF(ISNUMBER(G20),IF( (G20>=$F$4)*(H20<$F$2),G20, NA() ),NA()) -> #N/A | J20: =IF(ISNUMBER(G20),IF( (G20>=$F$4)*(H20>=$F$2),G20, NA() ),NA()) -> 42 | K20: =IF(ISNUMBER(G20),IF( (G20<$F$4)*(H20<$F$2),G20, NA() ),NA()) -> #N/A | L20: =IF(ISNUMBER(G20),IF( (G20<$F$4)*(H20>=$F$2),G20, NA() ),NA()) -> #N/A | R20: Pacers | S20: 69 | T20: 21 | U20: 86 | V20: 32
A21: 161061275622500290 | B21: 92 | C21: 39 | D21: 13 | E21: 40 | G21: =IF(C21="",NA(),C21) -> 39 | H21: =IF(E21="",NA(),E21) -> 40 | I21: =IF(ISNUMBER(G21),IF( (G21>=$F$4)*(H21<$F$2),G21, NA() ),NA()) -> 39 | J21: =IF(ISNUMBER(G21),IF( (G21>=$F$4)*(H21>=$F$2),G21, NA() ),NA()) -> #N/A | K21: =IF(ISNUMBER(G21),IF( (G21<$F$4)*(H21<$F$2),G21, NA() ),NA()) -> #N/A | L21: =IF(ISNUMBER(G21),IF( (G21<$F$4)*(H21>=$F$2),G21, NA() ),NA()) -> #N/A | R21: Pelicans | S21: 72 | T21: 12 | U21: 94 | V21: 38
... A31: 161061275622500448 | B31: 115 | C31: 51 | D31: 16 | E31: 48 | G31: =IF(C31="",NA(),C31) -> 51 | H31: =IF(E31="",NA(),E31) -> 48 | I31: =IF(ISNUMBER(G31),IF( (G31>=$F$4)*(H31<$F$2),G31, NA() ),NA()) -> 51 | J31: =IF(ISNUMBER(G31),IF( (G31>=$F$4)*(H31>=$F$2),G31, NA() ),NA()) -> #N/A | K31: =IF(ISNUMBER(G31),IF( (G31<$F$4)*(H31<$F$2),G31, NA() ),NA()) -> #N/A | L31: =IF(ISNUMBER(G31),IF( (G31<$F$4)*(H31>=$F$2),G31, NA() ),NA()) -> #N/A | R31: Wizards | S31: 57 | T31: 15 | U31: 98 | V31: 36
A32: 161061275622500465 | B32: 113 | C32: 45 | D32: 14 | E32: 54 | G32: =IF(C32="",NA(),C32) -> 45 | H32: =IF(E32="",NA(),E32) -> 54 | I32: =IF(ISNUMBER(G32),IF( (G32>=$F$4)*(H32<$F$2),G32, NA() ),NA()) -> 45 | J32: =IF(ISNUMBER(G32),IF( (G32>=$F$4)*(H32>=$F$2),G32, NA() ),NA()) -> #N/A | K32: =IF(ISNUMBER(G32),IF( (G32<$F$4)*(H32<$F$2),G32, NA() ),NA()) -> #N/A | L32: =IF(ISNUMBER(G32),IF( (G32<$F$4)*(H32>=$F$2),G32, NA() ),NA()) -> #N/A
A33: 161061275622500483 | B33: 129 | C33: 24 | D33: 23 | E33: 82 | G33: =IF(C33="",NA(),C33) -> 24 | H33: =IF(E33="",NA(),E33) -> 82 | I33: =IF(ISNUMBER(G33),IF( (G33>=$F$4)*(H33<$F$2),G33, NA() ),NA()) -> #N/A | J33: =IF(ISNUMBER(G33),IF( (G33>=$F$4)*(H33>=$F$2),G33, NA() ),NA()) -> #N/A | K33: =IF(ISNUMBER(G33),IF( (G33<$F$4)*(H33<$F$2),G33, NA() ),NA()) -> #N/A | L33: =IF(ISNUMBER(G33),IF( (G33<$F$4)*(H33>=$F$2),G33, NA() ),NA()) -> 24 | R33: LIMITES DE LA GRÁFICA
A34: 161061275622500499 | B34: 108 | C34: 51 | D34: 21 | E34: 36 | G34: =IF(C34="",NA(),C34) -> 51 | H34: =IF(E34="",NA(),E34) -> 36 | I34: =IF(ISNUMBER(G34),IF( (G34>=$F$4)*(H34<$F$2),G34, NA() ),NA()) -> 51 | J34: =IF(ISNUMBER(G34),IF( (G34>=$F$4)*(H34>=$F$2),G34, NA() ),NA()) -> #N/A | K34: =IF(ISNUMBER(G34),IF( (G34<$F$4)*(H34<$F$2),G34, NA() ),NA()) -> #N/A | L34: =IF(ISNUMBER(G34),IF( (G34<$F$4)*(H34>=$F$2),G34, NA() ),NA()) -> #N/A | R34: MinTriples | S34: MaxTriples | T34: PuntoMedio
A35: 161061275622500505 | B35: 97 | C35: 42 | D35: 9 | E35: 46 | G35: =IF(C35="",NA(),C35) -> 42 | H35: =IF(E35="",NA(),E35) -> 46 | I35: =IF(ISNUMBER(G35),IF( (G35>=$F$4)*(H35<$F$2),G35, NA() ),NA()) -> 42 | J35: =IF(ISNUMBER(G35),IF( (G35>=$F$4)*(H35>=$F$2),G35, NA() ),NA()) -> #N/A | K35: =IF(ISNUMBER(G35),IF( (G35<$F$4)*(H35<$F$2),G35, NA() ),NA()) -> #N/A | L35: =IF(ISNUMBER(G35),IF( (G35<$F$4)*(H35>=$F$2),G35, NA() ),NA()) -> #N/A | R35: =MIN(T2:T31) -> 9 | S35: =MAX(S2:S31) -> 87 | T35: =(R35+S35)/2 -> 48
A36: 161061275622500524 | B36: 117 | C36: 66 | D36: 5 | E36: 46 | G36: =IF(C36="",NA(),C36) -> 66 | H36: =IF(E36="",NA(),E36) -> 46 | I36: =IF(ISNUMBER(G36),IF( (G36>=$F$4)*(H36<$F$2),G36, NA() ),NA()) -> 66 | J36: =IF(ISNUMBER(G36),IF( (G36>=$F$4)*(H36>=$F$2),G36, NA() ),NA()) -> #N/A | K36: =IF(ISNUMBER(G36),IF( (G36<$F$4)*(H36<$F$2),G36, NA() ),NA()) -> #N/A | L36: =IF(ISNUMBER(G36),IF( (G36<$F$4)*(H36>=$F$2),G36, NA() ),NA()) -> #N/A | R36: MinArea | S36: MaxArea | T36: PuntoMedio
A37: 161061275622500538 | B37: 112 | C37: 48 | D37: 20 | E37: 44 | G37: =IF(C37="",NA(),C37) -> 48 | H37: =IF(E37="",NA(),E37) -> 44 | I37: =IF(ISNUMBER(G37),IF( (G37>=$F$4)*(H37<$F$2),G37, NA() ),NA()) -> 48 | J37: =IF(ISNUMBER(G37),IF( (G37>=$F$4)*(H37>=$F$2),G37, NA() ),NA()) -> #N/A | K37: =IF(ISNUMBER(G37),IF( (G37<$F$4)*(H37<$F$2),G37, NA() ),NA()) -> #N/A | L37: =IF(ISNUMBER(G37),IF( (G37<$F$4)*(H37>=$F$2),G37, NA() ),NA()) -> #N/A | R37: =MIN(V2:V31) -> 24 | S37: =MAX(U2:U31) -> 98 | T37: =(R37+S37)/2 -> 61
A38: 161061275622500555 | B38: 112 | C38: 51 | D38: 15 | E38: 46 | G38: =IF(C38="",NA(),C38) -> 51 | H38: =IF(E38="",NA(),E38) -> 46 | I38: =IF(ISNUMBER(G38),IF( (G38>=$F$4)*(H38<$F$2),G38, NA() ),NA()) -> 51 | J38: =IF(ISNUMBER(G38),IF( (G38>=$F$4)*(H38>=$F$2),G38, NA() ),NA()) -> #N/A | K38: =IF(ISNUMBER(G38),IF( (G38<$F$4)*(H38<$F$2),G38, NA() ),NA()) -> #N/A | L38: =IF(ISNUMBER(G38),IF( (G38<$F$4)*(H38>=$F$2),G38, NA() ),NA()) -> #N/A
A39: 161061275622500564 | B39: 121 | C39: 42 | D39: 19 | E39: 60 | G39: =IF(C39="",NA(),C39) -> 42 | H39: =IF(E39="",NA(),E39) -> 60 | I39: =IF(ISNUMBER(G39),IF( (G39>=$F$4)*(H39<$F$2),G39, NA() ),NA()) -> #N/A | J39: =IF(ISNUMBER(G39),IF( (G39>=$F$4)*(H39>=$F$2),G39, NA() ),NA()) -> 42 | K39: =IF(ISNUMBER(G39),IF( (G39<$F$4)*(H39<$F$2),G39, NA() ),NA()) -> #N/A | L39: =IF(ISNUMBER(G39),IF( (G39<$F$4)*(H39>=$F$2),G39, NA() ),NA()) -> #N/A
A40: 161061275622500579 | B40: 105 | C40: 51 | D40: 16 | E40: 38 | G40: =IF(C40="",NA(),C40) -> 51 | H40: =IF(E40="",NA(),E40) -> 38 | I40: =IF(ISNUMBER(G40),IF( (G40>=$F$4)*(H40<$F$2),G40, NA() ),NA()) -> 51 | J40: =IF(ISNUMBER(G40),IF( (G40>=$F$4)*(H40>=$F$2),G40, NA() ),NA()) -> #N/A | K40: =IF(ISNUMBER(G40),IF( (G40<$F$4)*(H40<$F$2),G40, NA() ),NA()) -> #N/A | L40: =IF(ISNUMBER(G40),IF( (G40<$F$4)*(H40>=$F$2),G40, NA() ),NA()) -> #N/A
A41: 161061275622500596 | B41: 106 | C41: 45 | D41: 23 | E41: 38 | G41: =IF(C41="",NA(),C41) -> 45 | H41: =IF(E41="",NA(),E41) -> 38 | I41: =IF(ISNUMBER(G41),IF( (G41>=$F$4)*(H41<$F$2),G41, NA() ),NA()) -> 45 | J41: =IF(ISNUMBER(G41),IF( (G41>=$F$4)*(H41>=$F$2),G41, NA() ),NA()) -> #N/A | K41: =IF(ISNUMBER(G41),IF( (G41<$F$4)*(H41<$F$2),G41, NA() ),NA()) -> #N/A | L41: =IF(ISNUMBER(G41),IF( (G41<$F$4)*(H41>=$F$2),G41, NA() ),NA()) -> #N/A
A42: 161061275622500610 | B42: 126 | C42: 60 | D42: 18 | E42: 48 | G42: =IF(C42="",NA(),C42) -> 60 | H42: =IF(E42="",NA(),E42) -> 48 | I42: =IF(ISNUMBER(G42),IF( (G42>=$F$4)*(H42<$F$2),G42, NA() ),NA()) -> 60 | J42: =IF(ISNUMBER(G42),IF( (G42>=$F$4)*(H42>=$F$2),G42, NA() ),NA()) -> #N/A | K42: =IF(ISNUMBER(G42),IF( (G42<$F$4)*(H42<$F$2),G42, NA() ),NA()) -> #N/A | L42: =IF(ISNUMBER(G42),IF( (G42<$F$4)*(H42>=$F$2),G42, NA() ),NA()) -> #N/A
A43: 161061275622500613 | B43: 116 | C43: 48 | D43: 20 | E43: 48 | G43: =IF(C43="",NA(),C43) -> 48 | H43: =IF(E43="",NA(),E43) -> 48 | I43: =IF(ISNUMBER(G43),IF( (G43>=$F$4)*(H43<$F$2),G43, NA() ),NA()) -> 48 | J43: =IF(ISNUMBER(G43),IF( (G43>=$F$4)*(H43>=$F$2),G43, NA() ),NA()) -> #N/A | K43: =IF(ISNUMBER(G43),IF( (G43<$F$4)*(H43<$F$2),G43, NA() ),NA()) -> #N/A | L43: =IF(ISNUMBER(G43),IF( (G43<$F$4)*(H43>=$F$2),G43, NA() ),NA()) -> #N/A
A44: 161061275622500636 | B44: 103 | C44: 33 | D44: 8 | E44: 62 | G44: =IF(C44="",NA(),C44) -> 33 | H44: =IF(E44="",NA(),E44) -> 62 | I44: =IF(ISNUMBER(G44),IF( (G44>=$F$4)*(H44<$F$2),G44, NA() ),NA()) -> #N/A | J44: =IF(ISNUMBER(G44),IF( (G44>=$F$4)*(H44>=$F$2),G44, NA() ),NA()) -> #N/A | K44: =IF(ISNUMBER(G44),IF( (G44<$F$4)*(H44<$F$2),G44, NA() ),NA()) -> #N/A | L44: =IF(ISNUMBER(G44),IF( (G44<$F$4)*(H44>=$F$2),G44, NA() ),NA()) -> 33
A45: 161061275622500655 | B45: 102 | C45: 21 | D45: 21 | E45: 60 | G45: =IF(C45="",NA(),C45) -> 21 | H45: =IF(E45="",NA(),E45) -> 60 | I45: =IF(ISNUMBER(G45),IF( (G45>=$F$4)*(H45<$F$2),G45, NA() ),NA()) -> #N/A | J45: =IF(ISNUMBER(G45),IF( (G45>=$F$4)*(H45>=$F$2),G45, NA() ),NA()) -> #N/A | K45: =IF(ISNUMBER(G45),IF( (G45<$F$4)*(H45<$F$2),G45, NA() ),NA()) -> #N/A | L45: =IF(ISNUMBER(G45),IF( (G45<$F$4)*(H45>=$F$2),G45, NA() ),NA()) -> 21
A46: 161061275622500669 | B46: 106 | C46: 15 | D46: 15 | E46: 76 | G46: =IF(C46="",NA(),C46) -> 15 | H46: =IF(E46="",NA(),E46) -> 76 | I46: =IF(ISNUMBER(G46),IF( (G46>=$F$4)*(H46<$F$2),G46, NA() ),NA()) -> #N/A | J46: =IF(ISNUMBER(G46),IF( (G46>=$F$4)*(H46>=$F$2),G46, NA() ),NA()) -> #N/A | K46: =IF(ISNUMBER(G46),IF( (G46<$F$4)*(H46<$F$2),G46, NA() ),NA()) -> #N/A | L46: =IF(ISNUMBER(G46),IF( (G46<$F$4)*(H46>=$F$2),G46, NA() ),NA()) -> 15
A47: 161061275622500685 | B47: 114 | C47: 48 | D47: 24 | E47: 42 | G47: =IF(C47="",NA(),C47) -> 48 | H47: =IF(E47="",NA(),E47) -> 42 | I47: =IF(ISNUMBER(G47),IF( (G47>=$F$4)*(H47<$F$2),G47, NA() ),NA()) -> 48 | J47: =IF(ISNUMBER(G47),IF( (G47>=$F$4)*(H47>=$F$2),G47, NA() ),NA()) -> #N/A | K47: =IF(ISNUMBER(G47),IF( (G47<$F$4)*(H47<$F$2),G47, NA() ),NA()) -> #N/A | L47: =IF(ISNUMBER(G47),IF( (G47<$F$4)*(H47>=$F$2),G47, NA() ),NA()) -> #N/A
A48: 161061275622500693 | B48: 126 | C48: 69 | D48: 13 | E48: 44 | G48: =IF(C48="",NA(),C48) -> 69 | H48: =IF(E48="",NA(),E48) -> 44 | I48: =IF(ISNUMBER(G48),IF( (G48>=$F$4)*(H48<$F$2),G48, NA() ),NA()) -> 69 | J48: =IF(ISNUMBER(G48),IF( (G48>=$F$4)*(H48>=$F$2),G48, NA() ),NA()) -> #N/A | K48: =IF(ISNUMBER(G48),IF( (G48<$F$4)*(H48<$F$2),G48, NA() ),NA()) -> #N/A | L48: =IF(ISNUMBER(G48),IF( (G48<$F$4)*(H48>=$F$2),G48, NA() ),NA()) -> #N/A
A49: 161061275622500709 | B49: 93 | C49: 57 | D49: 12 | E49: 24 | G49: =IF(C49="",NA(),C49) -> 57 | H49: =IF(E49="",NA(),E49) -> 24 | I49: =IF(ISNUMBER(G49),IF( (G49>=$F$4)*(H49<$F$2),G49, NA() ),NA()) -> 57 | J49: =IF(ISNUMBER(G49),IF( (G49>=$F$4)*(H49>=$F$2),G49, NA() ),NA()) -> #N/A | K49: =IF(ISNUMBER(G49),IF( (G49<$F$4)*(H49<$F$2),G49, NA() ),NA()) -> #N/A | L49: =IF(ISNUMBER(G49),IF( (G49<$F$4)*(H49>=$F$2),G49, NA() ),NA()) -> #N/A
...

Sheet Análisis_temporal
A1: Etiquetas de fila | B1: Puntos Anotados | C1: Asistencias | D1: % Tiro Real | E1: Posesiones Estimadas | F1: Calificación ofensiva | G1: Calificación defensiva | H1: Asistencias/Pérdidas | I1: % Tiros de Campo | J1: % Triples | K1: % Tiros Libres | L1: Rebotes Ofensivos | M1: Rebotes Defensivos | N1: Pérdidas | O1: Puntos tras Pérdida | P1: Puntos al Contraataque | Q1: Victoria | S1: num_fila | T1: Fecha | U1: =Dashboard!$S$9 -> % Triples | V1: Fecha | W1: Victoria | X1: Derrota
A2: 45952 | B2: 120 | C2: 23 | D2: 0.55907566 | E2: 74.32 | F2: 161.46394 | G2: 141.2567 | H2: 1.5333333 | I2: 0.474 | J2: 0.294 | K2: 0.714 | L2: 18 | M2: 33 | N2: 15 | O2: 19 | P2: 15 | Q2: 1 | S2: 1 | T2: =IF(L2="","",A2) -> 45952 | U2: =IF(L2="","",INDEX(A1:$M$213,2,MATCH($U$1,$A$1:$M$1,0))) -> 0.294 | V2: =IF(L2="",NA(),A2) -> 45952 | W2: =IF(Q2="",NA(),IF(Q2<>0,INDEX($A$2:$P$213,S2,MATCH($U$1,$A$1:$P$1,0)),NA())) -> 0.294 | X2: =IF(Q2="",NA(),IF(Q2=0,INDEX($A$2:$P$213,S2,MATCH($U$1,$A$1:$P$1,0)),NA())) -> #N/A
A3: 45954 | B3: 102 | C3: 23 | D3: 0.52795031 | E3: 63.6 | F3: 160.37736 | G3: 213.43481 | H3: 1.2777778 | I3: 0.411 | J3: 0.34 | K3: 0.8 | L3: 15 | M3: 22 | N3: 18 | O3: 21 | P3: 7 | Q3: 0 | S3: 2 | T3: =IF(L3="","",A3) -> 45954 | U3: =IF(L3="","",INDEX(A2:$M$213,2,MATCH($U$1,$A$1:$M$1,0))) -> 0.34 | V3: =IF(L3="",NA(),A3) -> 45954 | W3: =IF(Q3="",NA(),IF(Q3<>0,INDEX($A$2:$P$213,S3,MATCH($U$1,$A$1:$P$1,0)),NA())) -> #N/A | X3: =IF(Q3="",NA(),IF(Q3=0,INDEX($A$2:$P$213,S3,MATCH($U$1,$A$1:$P$1,0)),NA())) -> 0.34
A4: 45955 | B4: 111 | C4: 24 | D4: 0.56818182 | E4: 66.68 | F4: 166.46671 | G4: 176.20562 | H4: 1.2631579 | I4: 0.432 | J4: 0.34 | K4: 0.818 | L4: 12 | M4: 26 | N4: 19 | O4: 19 | P4: 11 | Q4: 0 | S4: 3 | T4: =IF(L4="","",A4) -> 45955 | U4: =IF(L4="","",INDEX(A3:$M$213,2,MATCH($U$1,$A$1:$M$1,0))) -> 0.34 | V4: =IF(L4="",NA(),A4) -> 45955 | W4: =IF(Q4="",NA(),IF(Q4<>0,INDEX($A$2:$P$213,S4,MATCH($U$1,$A$1:$P$1,0)),NA())) -> #N/A | X4: =IF(Q4="",NA(),IF(Q4=0,INDEX($A$2:$P$213,S4,MATCH($U$1,$A$1:$P$1,0)),NA())) -> 0.34
A5: 45957 | B5: 134 | C5: 37 | D5: 0.56001337 | E5: 87.64 | F5: 152.89822 | G5: 177.28674 | H5: 2.6428571 | I5: 0.425 | J5: 0.364 | K5: 0.774 | L5: 18 | M5: 30 | N5: 14 | O5: 19 | P5: 24 | Q5: 0 | S5: 4 | T5: =IF(L5="","",A5) -> 45957 | U5: =IF(L5="","",INDEX(A4:$M$213,2,MATCH($U$1,$A$1:$M$1,0))) -> 0.364 | V5: =IF(L5="",NA(),A5) -> 45957 | W5: =IF(Q5="",NA(),IF(Q5<>0,INDEX($A$2:$P$213,S5,MATCH($U$1,$A$1:$P$1,0)),NA())) -> #N/A | X5: =IF(Q5="",NA(),IF(Q5=0,INDEX($A$2:$P$213,S5,MATCH($U$1,$A$1:$P$1,0)),NA())) -> 0.364
A6: 45959 | B6: 113 | C6: 25 | D6: 0.60440736 | E6: 65.48 | F6: 172.57178 | G6: 156.76568 | H6: 1.25 | I6: 0.477 | J6: 0.4 | K6: 0.882 | L6: 8 | M6: 32 | N6: 20 | O6: 14 | P6: 12 | Q6: 0 | S6: 5 | T6: =IF(L6="","",A6) -> 45959 | U6: =IF(L6="","",INDEX(A5:$M$213,2,MATCH($U$1,$A$1:$M$1,0))) -> 0.4 | V6: =IF(L6="",NA(),A6) -> 45959 | W6: =IF(Q6="",NA(),IF(Q6<>0,INDEX($A$2:$P$213,S6,MATCH($U$1,$A$1:$P$1,0)),NA())) -> #N/A | X6: =IF(Q6="",NA(),IF(Q6=0,INDEX($A$2:$P$213,S6,MATCH($U$1,$A$1:$P$1,0)),NA())) -> 0.4
A7: 45961 | B7: 118 | C7: 30 | D7: 0.59644157 | E7: 81.92 | F7: 144.04297 | G7: 157.17092 | H7: 3.3333333 | I7: 0.473 | J7: 0.354 | K7: 0.833 | L7: 8 | M7: 36 | N7: 9 | O7: 29 | P7: 14 | Q7: 1 | S7: 6 | T7: =IF(L7="","",A7) -> 45961 | U7: =IF(L7="","",INDEX(A6:$M$213,2,MATCH($U$1,$A$1:$M$1,0))) -> 0.354 | V7: =IF(L7="",NA(),A7) -> 45961 | W7: =IF(Q7="",NA(),IF(Q7<>0,INDEX($A$2:$P$213,S7,MATCH($U$1,$A$1:$P$1,0)),NA())) -> 0.354 | X7: =IF(Q7="",NA(),IF(Q7=0,INDEX($A$2:$P$213,S7,MATCH($U$1,$A$1:$P$1,0)),NA())) -> #N/A
A8: 45963 | B8: 130 | C8: 34 | D8: 0.73297249 | E8: 63.68 | F8: 204.14573 | G8: 151.04967 | H8: 1.7 | I8: 0.582 | J8: 0.576 | K8: 0.864 | L8: 5 | M8: 34 | N8: 20 | O8: 21 | P8: 11 | Q8: 1 | S8: 7 | T8: =IF(L8="","",A8) -> 45963 | U8: =IF(L8="","",INDEX(A7:$M$213,2,MATCH($U$1,$A$1:$M$1,0))) -> 0.576 | V8: =IF(L8="",NA(),A8) -> 45963 | W8: =IF(Q8="",NA(),IF(Q8<>0,INDEX($A$2:$P$213,S8,MATCH($U$1,$A$1:$P$1,0)),NA())) -> 0.576 | X8: =IF(Q8="",NA(),IF(Q8=0,INDEX($A$2:$P$213,S8,MATCH($U$1,$A$1:$P$1,0)),NA())) -> #N/A
A9: 45965 | B9: 107 | C9: 25 | D9: 0.54569563 | E9: 65.04 | F9: 164.51415 | G9: 171.51163 | H9: 1.4705882 | I9: 0.44 | J9: 0.364 | K9: 0.938 | L9: 16 | M9: 30 | N9: 17 | O9: 12 | P9: 12 | Q9: 0 | S9: 8 | T9: =IF(L9="","",A9) -> 45965 | U9: =IF(L9="","",INDEX(A8:$M$213,2,MATCH($U$1,$A$1:$M$1,0))) -> 0.364 | V9: =IF(L9="",NA(),A9) -> 45965 | W9: =IF(Q9="",NA(),IF(Q9<>0,INDEX($A$2:$P$213,S9,MATCH($U$1,$A$1:$P$1,0)),NA())) -> #N/A | X9: =IF(Q9="",NA(),IF(Q9=0,INDEX($A$2:$P$213,S9,MATCH($U$1,$A$1:$P$1,0)),NA())) -> 0.364
A10: 45967 | B10: 115 | C10: 27 | D10: 0.57293743 | E10: 70.36 | F10: 163.44514 | G10: 154.07855 | H10: 1.8 | I10: 0.446 | J10: 0.388 | K10: 0.737 | L10: 15 | M10: 29 | N10: 15 | O10: 26 | P10: 12 | Q10: 1 | S10: 9 | T10: =IF(L10="","",A10) -> 45967 | U10: =IF(L10="","",INDEX(A9:$M$213,2,MATCH($U$1,$A$1:$M$1,0))) -> 0.388 | V10: =IF(L10="",NA(),A10) -> 45967 | W10: =IF(Q10="",NA(),IF(Q10<>0,INDEX($A$2:$P$213,S10,MATCH($U$1,$A$1:$P$1,0)),NA())) -> 0.388 | X10: =IF(Q10="",NA(),IF(Q10=0,INDEX($A$2:$P$213,S10,MATCH($U$1,$A$1:$P$1,0)),NA())) -> #N/A
A11: 45969 | B11: 114 | C11: 30 | D11: 0.61795317 | E11: 67.24 | F11: 169.54194 | G11: 149.44864 | H11: 2.5 | I11: 0.482 | J11: 0.421 | K11: 0.857 | L11: 13 | M11: 29 | N11: 12 | O11: 13 | P11: 19 | Q11: 1 | S11: 10 | T11: =IF(L11="","",A11) -> 45969 | U11: =IF(L11="","",INDEX(A10:$M$213,2,MATCH($U$1,$A$1:$M$1,0))) -> 0.421 | V11: =IF(L11="",NA(),A11) -> 45969 | W11: =IF(Q11="",NA(),IF(Q11<>0,INDEX($A$2:$P$213,S11,MATCH($U$1,$A$1:$P$1,0)),NA())) -> 0.421 | X11: =IF(Q11="",NA(),IF(Q11=0,INDEX($A$2:$P$213,S11,MATCH($U$1,$A$1:$P$1,0)),NA())) -> #N/A
A12: 45971 | B12: 121 | C12: 29 | D12: 0.66019206 | E12: 63.64 | F12: 190.13199 | G12: 162.14428 | H12: 1.6111111 | I12: 0.5 | J12: 0.442 | K12: 0.774 | L12: 10 | M12: 33 | N12: 18 | O12: 29 | P12: 9 | Q12: 1 | S12: 11 | T12: =IF(L12="","",A12) -> 45971 | U12: =IF(L12="","",INDEX(A11:$M$213,2,MATCH($U$1,$A$1:$M$1,0))) -> 0.442 | V12: =IF(L12="",NA(),A12) -> 45971 | W12: =IF(Q12="",NA(),IF(Q12<>0,INDEX($A$2:$P$213,S12,MATCH($U$1,$A$1:$P$1,0)),NA())) -> 0.442 | X12: =IF(Q12="",NA(),IF(Q12=0,INDEX($A$2:$P$213,S12,MATCH($U$1,$A$1:$P$1,0)),NA())) -> #N/A
A13: 45973 | B13: 123 | C13: 31 | D13: 0.5777903 | E13: 81.44 | F13: 151.03143 | G13: 171.48014 | H13: 2.5833333 | I13: 0.463 | J13: 0.4 | K13: 0.808 | L13: 13 | M13: 33 | N13: 12 | O13: 31 | P13: 21 | Q13: 1 | S13: 12 | T13: =IF(L13="","",A13) -> 45973 | U13: =IF(L13="","",INDEX(A12:$M$213,2,MATCH($U$1,$A$1:$M$1,0))) -> 0.4 | V13: =IF(L13="",NA(),A13) -> 45973 | W13: =IF(Q13="",NA(),IF(Q13<>0,INDEX($A$2:$P$213,S13,MATCH($U$1,$A$1:$P$1,0)),NA())) -> 0.4 | X13: =IF(Q13="",NA(),IF(Q13=0,INDEX($A$2:$P$213,S13,MATCH($U$1,$A$1:$P$1,0)),NA())) -> #N/A
... A89: 46139 | B89: 122 | C89: 24 | D89: 0.62860676 | E89: 75.04 | F89: 162.57996 | G89: 197.8852 | H89: 2 | I89: 0.533 | J89: 0.359 | K89: 0.75 | L89: 10 | M89: 23 | N89: 12 | O89: 16 | P89: 6 | Q89: 0 | S89: 88 | T89: =IF(L89="","",A89) -> 46139 | U89: =IF(L89="","",INDEX(A88:$M$213,2,MATCH($U$1,$A$1:$M$1,0))) -> 0.359 | V89: =IF(L89="",NA(),A89) -> 46139 | W89: =IF(Q89="",NA(),IF(Q89<>0,INDEX($A$2:$P$213,S89,MATCH($U$1,$A$1:$P$1,0)),NA())) -> #N/A | X89: =IF(Q89="",NA(),IF(Q89=0,INDEX($A$2:$P$213,S89,MATCH($U$1,$A$1:$P$1,0)),NA())) -> 0.359
S90: 89 | T90: =IF(L90="","",A90) | U90: =IF(L90="","",INDEX(A89:$M$213,2,MATCH($U$1,$A$1:$M$1,0))) | V90: =IF(L90="",NA(),A90) -> #N/A | W90: =IF(Q90="",NA(),IF(Q90<>0,INDEX($A$2:$P$213,S90,MATCH($U$1,$A$1:$P$1,0)),NA())) -> #N/A | X90: =IF(Q90="",NA(),IF(Q90=0,INDEX($A$2:$P$213,S90,MATCH($U$1,$A$1:$P$1,0)),NA())) -> #N/A
S91: 90 | T91: =IF(L91="","",A91) | U91: =IF(L91="","",INDEX(A90:$M$213,2,MATCH($U$1,$A$1:$M$1,0))) | V91: =IF(L91="",NA(),A91) -> #N/A | W91: =IF(Q91="",NA(),IF(Q91<>0,INDEX($A$2:$P$213,S91,MATCH($U$1,$A$1:$P$1,0)),NA())) -> #N/A | X91: =IF(Q91="",NA(),IF(Q91=0,INDEX($A$2:$P$213,S91,MATCH($U$1,$A$1:$P$1,0)),NA())) -> #N/A
S92: 91 | T92: =IF(L92="","",A92) | U92: =IF(L92="","",INDEX(A91:$M$213,2,MATCH($U$1,$A$1:$M$1,0))) | V92: =IF(L92="",NA(),A92) -> #N/A | W92: =IF(Q92="",NA(),IF(Q92<>0,INDEX($A$2:$P$213,S92,MATCH($U$1,$A$1:$P$1,0)),NA())) -> #N/A | X92: =IF(Q92="",NA(),IF(Q92=0,INDEX($A$2:$P$213,S92,MATCH($U$1,$A$1:$P$1,0)),NA())) -> #N/A
S93: 92 | T93: =IF(L93="","",A93) | U93: =IF(L93="","",INDEX(A92:$M$213,2,MATCH($U$1,$A$1:$M$1,0))) | V93: =IF(L93="",NA(),A93) -> #N/A | W93: =IF(Q93="",NA(),IF(Q93<>0,INDEX($A$2:$P$213,S93,MATCH($U$1,$A$1:$P$1,0)),NA())) -> #N/A | X93: =IF(Q93="",NA(),IF(Q93=0,INDEX($A$2:$P$213,S93,MATCH($U$1,$A$1:$P$1,0)),NA())) -> #N/A
S94: 93 | T94: =IF(L94="","",A94) | U94: =IF(L94="","",INDEX(A93:$M$213,2,MATCH($U$1,$A$1:$M$1,0))) | V94: =IF(L94="",NA(),A94) -> #N/A | W94: =IF(Q94="",NA(),IF(Q94<>0,INDEX($A$2:$P$213,S94,MATCH($U$1,$A$1:$P$1,0)),NA())) -> #N/A | X94: =IF(Q94="",NA(),IF(Q94=0,INDEX($A$2:$P$213,S94,MATCH($U$1,$A$1:$P$1,0)),NA())) -> #N/A
S95: 94 | T95: =IF(L95="","",A95) | U95: =IF(L95="","",INDEX(A94:$M$213,2,MATCH($U$1,$A$1:$M$1,0))) | V95: =IF(L95="",NA(),A95) -> #N/A | W95: =IF(Q95="",NA(),IF(Q95<>0,INDEX($A$2:$P$213,S95,MATCH($U$1,$A$1:$P$1,0)),NA())) -> #N/A | X95: =IF(Q95="",NA(),IF(Q95=0,INDEX($A$2:$P$213,S95,MATCH($U$1,$A$1:$P$1,0)),NA())) -> #N/A
S96: 95 | T96: =IF(L96="","",A96) | U96: =IF(L96="","",INDEX(A95:$M$213,2,MATCH($U$1,$A$1:$M$1,0))) | V96: =IF(L96="",NA(),A96) -> #N/A | W96: =IF(Q96="",NA(),IF(Q96<>0,INDEX($A$2:$P$213,S96,MATCH($U$1,$A$1:$P$1,0)),NA())) -> #N/A | X96: =IF(Q96="",NA(),IF(Q96=0,INDEX($A$2:$P$213,S96,MATCH($U$1,$A$1:$P$1,0)),NA())) -> #N/A
S97: 96 | T97: =IF(L97="","",A97) | U97: =IF(L97="","",INDEX(A96:$M$213,2,MATCH($U$1,$A$1:$M$1,0))) | V97: =IF(L97="",NA(),A97) -> #N/A | W97: =IF(Q97="",NA(),IF(Q97<>0,INDEX($A$2:$P$213,S97,MATCH($U$1,$A$1:$P$1,0)),NA())) -> #N/A | X97: =IF(Q97="",NA(),IF(Q97=0,INDEX($A$2:$P$213,S97,MATCH($U$1,$A$1:$P$1,0)),NA())) -> #N/A
S98: 97 | T98: =IF(L98="","",A98) | U98: =IF(L98="","",INDEX(A97:$M$213,2,MATCH($U$1,$A$1:$M$1,0))) | V98: =IF(L98="",NA(),A98) -> #N/A | W98: =IF(Q98="",NA(),IF(Q98<>0,INDEX($A$2:$P$213,S98,MATCH($U$1,$A$1:$P$1,0)),NA())) -> #N/A | X98: =IF(Q98="",NA(),IF(Q98=0,INDEX($A$2:$P$213,S98,MATCH($U$1,$A$1:$P$1,0)),NA())) -> #N/A
S99: 98 | T99: =IF(L99="","",A99) | U99: =IF(L99="","",INDEX(A98:$M$213,2,MATCH($U$1,$A$1:$M$1,0))) | V99: =IF(L99="",NA(),A99) -> #N/A | W99: =IF(Q99="",NA(),IF(Q99<>0,INDEX($A$2:$P$213,S99,MATCH($U$1,$A$1:$P$1,0)),NA())) -> #N/A | X99: =IF(Q99="",NA(),IF(Q99=0,INDEX($A$2:$P$213,S99,MATCH($U$1,$A$1:$P$1,0)),NA())) -> #N/A
S100: 99 | T100: =IF(L100="","",A100) | U100: =IF(L100="","",INDEX(A99:$M$213,2,MATCH($U$1,$A$1:$M$1,0))) | V100: =IF(L100="",NA(),A100) -> #N/A | W100: =IF(Q100="",NA(),IF(Q100<>0,INDEX($A$2:$P$213,S100,MATCH($U$1,$A$1:$P$1,0)),NA())) -> #N/A | X100: =IF(Q100="",NA(),IF(Q100=0,INDEX($A$2:$P$213,S100,MATCH($U$1,$A$1:$P$1,0)),NA())) -> #N/A
S101: 100 | T101: =IF(L101="","",A101) | U101: =IF(L101="","",INDEX(A100:$M$213,2,MATCH($U$1,$A$1:$M$1,0))) | V101: =IF(L101="",NA(),A101) -> #N/A | W101: =IF(Q101="",NA(),IF(Q101<>0,INDEX($A$2:$P$213,S101,MATCH($U$1,$A$1:$P$1,0)),NA())) -> #N/A | X101: =IF(Q101="",NA(),IF(Q101=0,INDEX($A$2:$P$213,S101,MATCH($U$1,$A$1:$P$1,0)),NA())) -> #N/A
... S213: 212 | T213: =IF(L213="","",A213) | U213: =IF(L213="","",INDEX(A212:$M$213,2,MATCH($U$1,$A$1:$M$1,0))) | V213: =IF(L213="",NA(),A213) -> #N/A | W213: =IF(Q213="",NA(),IF(Q213<>0,INDEX($A$2:$P$213,S213,MATCH($U$1,$A$1:$P$1,0)),NA())) -> #N/A | X213: =IF(Q213="",NA(),IF(Q213=0,INDEX($A$2:$P$213,S213,MATCH($U$1,$A$1:$P$1,0)),NA())) -> #N/A

Sheet Análisis_TOP
A1: Teams | B1: Puntos Anotados | C1: Asistencias | D1: % Tiro Real | E1: Posesiones Estimadas | F1: Calificación ofensiva | G1: Calificación defensiva | H1: Asistencias/Pérdidas | I1: % Tiros de Campo | J1: % Triples | K1: % Tiros Libres | L1: Rebotes Ofensivos | M1: Rebotes Defensivos | N1: Pérdidas | O1: Puntos tras Pérdida | P1: Puntos al Contraataque | Q1: Victoria
A2: 76ers | B2: 114.30851 | C2: 24.12766 | D2: 0.5709617 | E2: 76.065957 | F2: 151.10218 | G2: 159.12418 | H2: 2.1369766 | I2: 0.46080851 | J2: 0.34276596 | K2: 0.80538298 | L2: 11.351064 | M2: 31.595745 | N2: 12.765957 | O2: 18.276596 | P2: 15.968085 | Q2: 50
A3: Bucks | B3: 110.63415 | C3: 25.804878 | D3: 0.58939603 | E3: 70.526341 | F3: 157.67824 | G3: 156.65479 | H3: 1.9163225 | I3: 0.47723171 | J3: 0.388 | K3: 0.72746341 | L3: 8.9146341 | M3: 31.829268 | N3: 14.463415 | O3: 15.670732 | P3: 11.804878 | Q3: 32
A4: Bulls | B4: 116.30488 | C4: 28.47561 | D4: 0.58010436 | E4: 75.250732 | F4: 155.03287 | G4: 152.29399 | H4: 2.134976 | I4: 0.4685122 | J4: 0.35426829 | K4: 0.7777439 | L4: 10.353659 | M4: 34.695122 | N4: 14.634146 | O4: 15.426829 | P4: 17.414634 | Q4: 31
A5: Cavaliers | B5: 117.44 | C5: 27.11 | D5: 0.59161998 | E5: 73.954 | F5: 159.68468 | G5: 157.00352 | H5: 2.162309 | I5: 0.47808 | J5: 0.35651 | K5: 0.76889 | L5: 11.7 | M5: 32.09 | N5: 13.75 | O5: 18.25 | P5: 13.03 | Q5: 60
A6: Celtics | B6: 114.20225 | C6: 24.573034 | D6: 0.58132567 | E6: 74.365843 | F6: 154.29957 | G6: 146.03872 | H6: 2.4166917 | I6: 0.46508989 | J6: 0.36416854 | K6: 0.79648315 | L6: 12.47191 | M6: 33.932584 | N6: 11.47191 | O6: 15.561798 | P6: 11.775281 | Q6: 59
A7: Clippers | B7: 113.85542 | C7: 23.819277 | D7: 0.60349899 | E7: 71.331084 | F7: 160.79371 | G7: 158.53829 | H7: 2.0133396 | I7: 0.48580723 | J7: 0.36449398 | K7: 0.8276506 | L7: 9.5542169 | M7: 30.987952 | N7: 13.590361 | O7: 18.73494 | P7: 13.807229 | Q7: 42
A8: Grizzlies | B8: 114.67073 | C8: 27.841463 | D8: 0.57099648 | E8: 74.835122 | F8: 154.31351 | G8: 165.00961 | H8: 2.1228975 | I8: 0.45729268 | J8: 0.35287805 | K8: 0.79508537 | L8: 11.170732 | M8: 30.95122 | N8: 14.634146 | O8: 17.97561 | P8: 15.036585 | Q8: 25
A9: Hawks | B9: 117.22727 | C9: 29.590909 | D9: 0.58136765 | E9: 76.577273 | F9: 153.90484 | G9: 158.93351 | H9: 2.4737015 | I9: 0.47205682 | J9: 0.36585227 | K9: 0.76463636 | L9: 10.852273 | M9: 32.227273 | N9: 13.443182 | O9: 20.25 | P9: 17.659091 | Q9: 48
A10: Heat | B10: 120.92771 | C10: 28.987952 | D10: 0.5798258 | E10: 79.453012 | F10: 152.75721 | G10: 154.38012 | H10: 2.4767949 | I10: 0.46896386 | J10: 0.35981928 | K10: 0.79387952 | L10: 11.831325 | M10: 34.46988 | N10: 13.048193 | O10: 19.518072 | P10: 18.385542 | Q10: 43
A11: Hornets | B11: 115.83333 | C11: 26.22619 | D11: 0.58812043 | E11: 71.51381 | F11: 163.64505 | G11: 149.96753 | H11: 2.0506595 | I11: 0.45946429 | J11: 0.37653571 | K11: 0.82490476 | L11: 12.761905 | M11: 33.261905 | N11: 14.369048 | O11: 15.559524 | P11: 13.083333 | Q11: 45
A12: Jazz | B12: 117.58537 | C12: 29.621951 | D12: 0.57622939 | E12: 75.185854 | F12: 157.58679 | G12: 164.77866 | H12: 2.1091538 | I12: 0.46776829 | J12: 0.3455 | K12: 0.77895122 | L12: 12 | M12: 31.817073 | N12: 15.012195 | O12: 17.97561 | P12: 17.609756 | Q12: 22
A13: Kings | B13: 111 | C13: 25.54878 | D13: 0.56081914 | E13: 73.826829 | F13: 151.41875 | G13: 161.59606 | H13: 2.1418102 | I13: 0.46762195 | J13: 0.3404878 | K13: 0.7662561 | L13: 11.5 | M13: 30.768293 | N13: 13.719512 | O13: 16.378049 | P13: 13.707317 | Q13: 22
... A31: Wizards | B31: 112.90244 | C31: 25.04878 | D31: 0.56702964 | E31: 73.557561 | F31: 154.58583 | G31: 162.25592 | H31: 1.7865895 | I31: 0.46296341 | J31: 0.35667073 | K31: 0.76704878 | L31: 10.97561 | M31: 30.926829 | N31: 15.146341 | O31: 16.060976 | P31: 14.47561 | Q31: 17
A33: Jerarquía | B33: =Dashboard!$S$9 -> % Triples | C33: Teams | H33: teamScore
A34: =RANK(B34,$B$34:$B$63) -> 25 | B34: =IF(Q2="","",INDEX(A1:$P$31,2,MATCH($B$33,$A$1:$P$1,0))) -> 0.34276596 | C34: =A2 -> 76ers | E34: TOP 5 bests teams | I34: TOP 5 worsts teams
A35: =RANK(B35,$B$34:$B$63) -> 2 | B35: =IF(Q3="","",INDEX(A2:$P$31,2,MATCH($B$33,$A$1:$P$1,0))) -> 0.388 | C35: =A3 -> Bucks | E35: Top | F35: =Dashboard!$S$9 -> % Triples | G35: Teams | I35: Top | J35: =Dashboard!$S$9 -> % Triples | K35: Teams
A36: =RANK(B36,$B$34:$B$63) -> 21 | B36: =IF(Q4="","",INDEX(A3:$P$31,2,MATCH($B$33,$A$1:$P$1,0))) -> 0.35426829 | C36: =A4 -> Bulls | E36: 1 | F36: =VLOOKUP(E36,$A$34:$C$63,2,0) -> 0.38994318 | G36: =VLOOKUP(E36,$A$34:$C$63,3,0) -> Nuggets | I36: 30 | J36: =VLOOKUP(I36,$A$34:$C$63,2,0) -> 0.33881319 | K36: =VLOOKUP(I36,$A$34:$C$63,3,0) -> Magic
A37: =RANK(B37,$B$34:$B$63) -> 18 | B37: =IF(Q5="","",INDEX(A4:$P$31,2,MATCH($B$33,$A$1:$P$1,0))) -> 0.35651 | C37: =A5 -> Cavaliers | E37: 2 | F37: =VLOOKUP(E37,$A$34:$C$63,2,0) -> 0.388 | G37: =VLOOKUP(E37,$A$34:$C$63,3,0) -> Bucks | I37: 29 | J37: =VLOOKUP(I37,$A$34:$C$63,2,0) -> 0.33919512 | K37: =VLOOKUP(I37,$A$34:$C$63,3,0) -> Mavericks
A38: =RANK(B38,$B$34:$B$63) -> 9 | B38: =IF(Q6="","",INDEX(A5:$P$31,2,MATCH($B$33,$A$1:$P$1,0))) -> 0.36416854 | C38: =A6 -> Celtics | E38: 3 | F38: =VLOOKUP(E38,$A$34:$C$63,2,0) -> 0.37653571 | G38: =VLOOKUP(E38,$A$34:$C$63,3,0) -> Hornets | I38: 28 | J38: =VLOOKUP(I38,$A$34:$C$63,2,0) -> 0.34006818 | K38: =VLOOKUP(I38,$A$34:$C$63,3,0) -> Trail Blazers
A39: =RANK(B39,$B$34:$B$63) -> 8 | B39: =IF(Q7="","",INDEX(A6:$P$31,2,MATCH($B$33,$A$1:$P$1,0))) -> 0.36449398 | C39: =A7 -> Clippers | E39: 4 | F39: =VLOOKUP(E39,$A$34:$C$63,2,0) -> 0.37476471 | G39: =VLOOKUP(E39,$A$34:$C$63,3,0) -> Knicks | I39: 27 | J39: =VLOOKUP(I39,$A$34:$C$63,2,0) -> 0.3404878 | K39: =VLOOKUP(I39,$A$34:$C$63,3,0) -> Kings
A40: =RANK(B40,$B$34:$B$63) -> 22 | B40: =IF(Q8="","",INDEX(A7:$P$31,2,MATCH($B$33,$A$1:$P$1,0))) -> 0.35287805 | C40: =A8 -> Grizzlies | E40: 5 | F40: =VLOOKUP(E40,$A$34:$C$63,2,0) -> 0.36775532 | G40: =VLOOKUP(E40,$A$34:$C$63,3,0) -> Timberwolves | I40: 26 | J40: =VLOOKUP(I40,$A$34:$C$63,2,0) -> 0.34142683 | K40: =VLOOKUP(I40,$A$34:$C$63,3,0) -> Nets
A41: =RANK(B41,$B$34:$B$63) -> 6 | B41: =IF(Q9="","",INDEX(A8:$P$31,2,MATCH($B$33,$A$1:$P$1,0))) -> 0.36585227 | C41: =A9 -> Hawks
A42: =RANK(B42,$B$34:$B$63) -> 12 | B42: =IF(Q10="","",INDEX(A9:$P$31,2,MATCH($B$33,$A$1:$P$1,0))) -> 0.35981928 | C42: =A10 -> Heat | E42: TOP 5 bests teams | I42: TOP 5 worsts teams
A43: =RANK(B43,$B$34:$B$63) -> 3 | B43: =IF(Q11="","",INDEX(A10:$P$31,2,MATCH($B$33,$A$1:$P$1,0))) -> 0.37653571 | C43: =A11 -> Hornets | E43: Top | F43: =Dashboard!$S$9 -> % Triples | G43: Teams | I43: Top | J43: =Dashboard!$S$9 -> % Triples | K43: Teams
A44: =RANK(B44,$B$34:$B$63) -> 23 | B44: =IF(Q12="","",INDEX(A11:$P$31,2,MATCH($B$33,$A$1:$P$1,0))) -> 0.3455 | C44: =A12 -> Jazz | E44: 1 | F44: =IF(ISNUMBER(FIND("%",$F$43,1)),ROUND(F36*100,2) &" %",ROUND(F36,2)) -> 38,99 % | G44: =G36 -> Nuggets | I44: 30 | J44: =IF(ISNUMBER(FIND("%",$J$43,1)),ROUND(J36*100,2) &" %",ROUND(J36,2)) -> 33,88 % | K44: =K36 -> Magic
A45: =RANK(B45,$B$34:$B$63) -> 27 | B45: =IF(Q13="","",INDEX(A12:$P$31,2,MATCH($B$33,$A$1:$P$1,0))) -> 0.3404878 | C45: =A13 -> Kings | E45: 2 | F45: =IF(ISNUMBER(FIND("%",$F$43,1)),ROUND(F37*100,2) &" %",ROUND(F37,2)) -> 38,8 % | G45: =G37 -> Bucks | I45: 29 | J45: =IF(ISNUMBER(FIND("%",$J$43,1)),ROUND(J37*100,2) &" %",ROUND(J37,2)) -> 33,92 % | K45: =K37 -> Mavericks
A46: =RANK(B46,$B$34:$B$63) -> 4 | B46: =IF(Q14="","",INDEX(A13:$P$31,2,MATCH($B$33,$A$1:$P$1,0))) -> 0.37476471 | C46: =A14 -> Knicks | E46: 3 | F46: =IF(ISNUMBER(FIND("%",$F$43,1)),ROUND(F38*100,2) &" %",ROUND(F38,2)) -> 37,65 % | G46: =G38 -> Hornets | I46: 28 | J46: =IF(ISNUMBER(FIND("%",$J$43,1)),ROUND(J38*100,2) &" %",ROUND(J38,2)) -> 34,01 % | K46: =K38 -> Trail Blazers
A47: =RANK(B47,$B$34:$B$63) -> 10 | B47: =IF(Q15="","",INDEX(A14:$P$31,2,MATCH($B$33,$A$1:$P$1,0))) -> 0.36367391 | C47: =A15 -> Lakers | E47: 4 | F47: =IF(ISNUMBER(FIND("%",$F$43,1)),ROUND(F39*100,2) &" %",ROUND(F39,2)) -> 37,48 % | G47: =G39 -> Knicks | I47: 27 | J47: =IF(ISNUMBER(FIND("%",$J$43,1)),ROUND(J39*100,2) &" %",ROUND(J39,2)) -> 34,05 % | K47: =K39 -> Kings
A48: =RANK(B48,$B$34:$B$63) -> 30 | B48: =IF(Q16="","",INDEX(A15:$P$31,2,MATCH($B$33,$A$1:$P$1,0))) -> 0.33881319 | C48: =A16 -> Magic | E48: 5 | F48: =IF(ISNUMBER(FIND("%",$F$43,1)),ROUND(F40*100,2) &" %",ROUND(F40,2)) -> 36,78 % | G48: =G40 -> Timberwolves | I48: 26 | J48: =IF(ISNUMBER(FIND("%",$J$43,1)),ROUND(J40*100,2) &" %",ROUND(J40,2)) -> 34,14 % | K48: =K40 -> Nets
